{"paper_only":true,"authenticated_execution":false,"real_order_submission":false,"real_capital_at_risk":false,"automatic_promotion":false,"execution_authority":false,"schema":"polymarket_v7_native_exact_arb_ws_frame_v1","model_sha":"f50147e18e02ebed76cabe900b708e4d9479e603","observer_session_id":"1790267378940-30808","session_manifest_sha256":"029412640e461b7cef08522eb6b6bce381d52d8001b3032f3af1960a7bd52ea0","feed_frame_sequence":1,"connection_epoch":1,"source_frame_valid":true,"decoded_events":28,"receive_wall_ms":1790267379153,"receive_monotonic_ns":1533843623652875,"decode_complete_monotonic_ns":1533843624550541,"graph_decision_start_ns":1533843625653791,"payload_sha256":"80840d0e203363e7020b94e021bdf2dd599577021d59dcb4401147b4a4da3896","payload":"[{\"market\":\"0xc48e17e33742004e4ec5d3386d05f7d723f1c2da37b5cbc56e9ce432e13d8ed4\",\"asset_id\":\"61335977902549040838647614340959106920439456466051953454810638023705765740133\",\"timestamp\":\"1790267353913\",\"hash\":\"d74400f187d2ac32b0882f6d6c50a25554d10383\",\"bids\":[{\"price\":\"0.01\",\"size\":\"6.39\"},{\"price\":\"0.02\",\"size\":\"527\"},{\"price\":\"0.08\",\"size\":\"50\"},{\"price\":\"0.13\",\"size\":\"46.4\"},{\"price\":\"0.18\",\"size\":\"30\"},{\"price\":\"0.21\",\"size\":\"300\"},{\"price\":\"0.22\",\"size\":\"50\"},{\"price\":\"0.25\",\"size\":\"20\"},{\"price\":\"0.26\",\"size\":\"500\"},{\"price\":\"0.29\",\"size\":\"500\"},{\"price\":\"0.32\",\"size\":\"489.69\"},{\"price\":\"0.33\",\"size\":\"884.67\"},{\"price\":\"0.34\",\"size\":\"20.58\"},{\"price\":\"0.35\",\"size\":\"300\"},{\"price\":\"0.36\",\"size\":\"181.29\"},{\"price\":\"0.37\",\"size\":\"50\"},{\"price\":\"0.38\",\"size\":\"5\"},{\"price\":\"0.4\",\"size\":\"750.03\"},{\"price\":\"0.41\",\"size\":\"106.33\"}],\"asks\":[{\"price\":\"0.99\",\"size\":\"320875\"},{\"price\":\"0.98\",\"size\":\"12588.76\"},{\"price\":\"0.97\",\"size\":\"11437.49\"},{\"price\":\"0.96\",\"size\":\"1468.76\"},{\"price\":\"0.95\",\"size\":\"1725\"},{\"price\":\"0.94\",\"size\":\"500\"},{\"price\":\"0.93\",\"size\":\"770\"},{\"price\":\"0.92\",\"size\":\"500\"},{\"price\":\"0.9\",\"size\":\"250\"},{\"price\":\"0.89\",\"size\":\"750\"},{\"price\":\"0.8\",\"size\":\"250\"},{\"price\":\"0.7\",\"size\":\"1000\"},{\"price\":\"0.69\",\"size\":\"50\"},{\"price\":\"0.6\",\"size\":\"1000\"},{\"price\":\"0.59\",\"size\":\"620\"},{\"price\":\"0.58\",\"size\":\"16.66\"},{\"price\":\"0.46\",\"size\":\"120\"},{\"price\":\"0.45\",\"size\":\"2382.88\"},{\"price\":\"0.44\",\"size\":\"2313.21\"},{\"price\":\"0.43\",\"size\":\"5\"}],\"tick_size\":\"0.01\",\"event_type\":\"book\",\"last_trade_price\":\"0.420\"},{\"market\":\"0x9027a12cbbf78e9bff760402ab106732fa5a4af2002e4f48e5cc406ac1447800\",\"asset_id\":\"74866639935465906228822387344939614806982371503507376045493150406757418241698\",\"timestamp\":\"1790267321830\",\"hash\":\"bdea183fd5510c233b804eb0f5a044d8fba1d374\",\"bids\":[{\"price\":\"0.01\",\"size\":\"115262.9\"},{\"price\":\"0.02\",\"size\":\"102500\"},{\"price\":\"0.03\",\"size\":\"5000\"},{\"price\":\"0.04\",\"size\":\"9.13\"},{\"price\":\"0.07\",\"size\":\"11857.14\"},{\"price\":\"0.1\",\"size\":\"31211\"},{\"price\":\"0.14\",\"size\":\"1785.71\"},{\"price\":\"0.2\",\"size\":\"17900\"},{\"price\":\"0.22\",\"size\":\"1363.63\"},{\"price\":\"0.27\",\"size\":\"30\"},{\"price\":\"0.3\",\"size\":\"10866.66\"},{\"price\":\"0.31\",\"size\":\"10483.85\"},{\"price\":\"0.32\",\"size\":\"4500\"},{\"price\":\"0.34\",\"size\":\"800\"},{\"price\":\"0.35\",\"size\":\"4500\"},{\"price\":\"0.36\",\"size\":\"50\"},{\"price\":\"0.38\",\"size\":\"50\"},{\"price\":\"0.41\",\"size\":\"305.58\"},{\"price\":\"0.49\",\"size\":\"100\"},{\"price\":\"0.5\",\"size\":\"122.01\"},{\"price\":\"0.52\",\"size\":\"100\"},{\"price\":\"0.66\",\"size\":\"15\"},{\"price\":\"0.68\",\"size\":\"499.99\"},{\"price\":\"0.69\",\"size\":\"5.97\"},{\"price\":\"0.7\",\"size\":\"32.46\"},{\"price\":\"0.71\",\"size\":\"30\"},{\"price\":\"0.72\",\"size\":\"30\"},{\"price\":\"0.73\",\"size\":\"530\"},{\"price\":\"0.74\",\"size\":\"149.96\"},{\"price\":\"0.75\",\"size\":\"91.07\"},{\"price\":\"0.76\",\"size\":\"30\"},{\"price\":\"0.77\",\"size\":\"80.1\"},{\"price\":\"0.78\",\"size\":\"30\"}],\"asks\":[{\"price\":\"0.99\",\"size\":\"12005.14\"},{\"price\":\"0.98\",\"size\":\"276.54\"},{\"price\":\"0.97\",\"size\":\"166.6\"},{\"price\":\"0.96\",\"size\":\"925\"},{\"price\":\"0.95\",\"size\":\"135.17\"},{\"price\":\"0.94\",\"size\":\"535.87\"},{\"price\":\"0.93\",\"size\":\"71.4\"},{\"price\":\"0.92\",\"size\":\"443.03\"},{\"price\":\"0.91\",\"size\":\"40\"},{\"price\":\"0.9\",\"size\":\"30\"},{\"price\":\"0.89\",\"size\":\"55\"},{\"price\":\"0.88\",\"size\":\"29.93\"},{\"price\":\"0.87\",\"size\":\"233.78\"},{\"price\":\"0.86\",\"size\":\"315.02\"},{\"price\":\"0.85\",\"size\":\"1607.69\"},{\"price\":\"0.84\",\"size\":\"269.97\"},{\"price\":\"0.83\",\"size\":\"165.96\"},{\"price\":\"0.81\",\"size\":\"27\"},{\"price\":\"0.8\",\"size\":\"71.03\"}],\"tick_size\":\"0.01\",\"event_type\":\"book\",\"last_trade_price\":\"0.780\"},{\"market\":\"0x16fcfe6c4bc8bf2fd210f1e3b5b0d55a2115a437923dc5730d63acb62c3366c9\",\"asset_id\":\"69170306473064163780812013647523990069387767302750674849421091155270068626385\",\"timestamp\":\"1790267338767\",\"hash\":\"1a1790b3a7da8419b6b1cd984b931e5de1a652e0\",\"bids\":[{\"price\":\"0.001\",\"size\":\"1123110\"},{\"price\":\"0.002\",\"size\":\"50010.18\"},{\"price\":\"0.003\",\"size\":\"3000\"},{\"price\":\"0.004\",\"size\":\"90000\"},{\"price\":\"0.005\",\"size\":\"2000\"},{\"price\":\"0.006\",\"size\":\"6.18\"},{\"price\":\"0.01\",\"size\":\"20\"},{\"price\":\"0.012\",\"size\":\"9000\"},{\"price\":\"0.013\",\"size\":\"1000\"},{\"price\":\"0.023\",\"size\":\"500\"},{\"price\":\"0.024\",\"size\":\"14.35\"},{\"price\":\"0.16\",\"size\":\"1000\"},{\"price\":\"0.161\",\"size\":\"50\"},{\"price\":\"0.25\",\"size\":\"16.57\"},{\"price\":\"0.252\",\"size\":\"21.01\"},{\"price\":\"0.301\",\"size\":\"7.27\"},{\"price\":\"0.31\",\"size\":\"8.01\"},{\"price\":\"0.51\",\"size\":\"50\"},{\"price\":\"0.511\",\"size\":\"8.84\"}],\"asks\":[{\"price\":\"0.999\",\"size\":\"2005.85\"},{\"price\":\"0.998\",\"size\":\"2005\"},{\"price\":\"0.997\",\"size\":\"1112.63\"},{\"price\":\"0.996\",\"size\":\"800\"},{\"price\":\"0.995\",\"size\":\"48.98\"},{\"price\":\"0.993\",\"size\":\"50\"},{\"price\":\"0.99\",\"size\":\"20\"},{\"price\":\"0.989\",\"size\":\"7.82\"},{\"price\":\"0.978\",\"size\":\"53\"},{\"price\":\"0.977\",\"size\":\"55\"},{\"price\":\"0.973\",\"size\":\"102\"},{\"price\":\"0.97\",\"size\":\"82\"},{\"price\":\"0.967\",\"size\":\"56\"},{\"price\":\"0.956\",\"size\":\"155\"},{\"price\":\"0.948\",\"size\":\"195.28\"},{\"price\":\"0.947\",\"size\":\"100\"},{\"price\":\"0.946\",\"size\":\"5.18\"},{\"price\":\"0.945\",\"size\":\"36\"},{\"price\":\"0.85\",\"size\":\"10\"},{\"price\":\"0.8\",\"size\":\"10\"},{\"price\":\"0.75\",\"size\":\"10\"},{\"price\":\"0.7\",\"size\":\"10\"},{\"price\":\"0.669\",\"size\":\"393.99\"},{\"price\":\"0.668\",\"size\":\"243.28\"},{\"price\":\"0.667\",\"size\":\"8\"},{\"price\":\"0.666\",\"size\":\"92.05\"},{\"price\":\"0.663\",\"size\":\"11\"},{\"price\":\"0.662\",\"size\":\"48.29\"}],\"tick_size\":\"0.001\",\"event_type\":\"book\",\"last_trade_price\":\"0.489\"},{\"market\":\"0x77a4012e47d506eee2a992032c11dab236bb56cac17a994bc2db3f7467cd97d1\",\"asset_id\":\"33658047392919238444353129436813170820769777551810148530519389731519208048432\",\"timestamp\":\"1790267327173\",\"hash\":\"67572b4bcd5ac87f1909379cc55057c8c281b65e\",\"bids\":[{\"price\":\"0.001\",\"size\":\"9136.18\"},{\"price\":\"0.002\",\"size\":\"720\"},{\"price\":\"0.003\",\"size\":\"486.54\"},{\"price\":\"0.004\",\"size\":\"275\"},{\"price\":\"0.005\",\"size\":\"220\"},{\"price\":\"0.01\",\"size\":\"115123.31\"},{\"price\":\"0.011\",\"size\":\"7.39\"},{\"price\":\"0.02\",\"size\":\"102500\"},{\"price\":\"0.03\",\"size\":\"5000\"},{\"price\":\"0.06\",\"size\":\"3333.33\"},{\"price\":\"0.061\",\"size\":\"5.46\"},{\"price\":\"0.092\",\"size\":\"20\"},{\"price\":\"0.1\",\"size\":\"31160\"},{\"price\":\"0.151\",\"size\":\"22847.62\"},{\"price\":\"0.18\",\"size\":\"1666.66\"},{\"price\":\"0.2\",\"size\":\"90\"},{\"price\":\"0.22\",\"size\":\"1363.63\"},{\"price\":\"0.26\",\"size\":\"53.06\"},{\"price\":\"0.3\",\"size\":\"10866.66\"},{\"price\":\"0.329\",\"size\":\"1863.82\"},{\"price\":\"0.508\",\"size\":\"200\"},{\"price\":\"0.51\",\"size\":\"20\"},{\"price\":\"0.55\",\"size\":\"20\"},{\"price\":\"0.627\",\"size\":\"294.33\"},{\"price\":\"0.631\",\"size\":\"500\"},{\"price\":\"0.636\",\"size\":\"300\"},{\"price\":\"0.637\",\"size\":\"40.34\"},{\"price\":\"0.64\",\"size\":\"30\"},{\"price\":\"0.723\",\"size\":\"222.4\"},{\"price\":\"0.724\",\"size\":\"9.66\"},{\"price\":\"0.737\",\"size\":\"31.02\"},{\"price\":\"0.738\",\"size\":\"30.99\"},{\"price\":\"0.739\",\"size\":\"30.95\"},{\"price\":\"0.74\",\"size\":\"30.92\"},{\"price\":\"0.741\",\"size\":\"30.89\"},{\"price\":\"0.742\",\"size\":\"30.86\"},{\"price\":\"0.743\",\"size\":\"30.83\"},{\"price\":\"0.744\",\"size\":\"30.8\"},{\"price\":\"0.745\",\"size\":\"30.76\"},{\"price\":\"0.746\",\"size\":\"30.73\"},{\"price\":\"0.748\",\"size\":\"31.98\"},{\"price\":\"0.749\",\"size\":\"31.94\"},{\"price\":\"0.767\",\"size\":\"100\"},{\"price\":\"0.768\",\"size\":\"176.46\"},{\"price\":\"0.769\",\"size\":\"456.44\"},{\"price\":\"0.771\",\"size\":\"30\"},{\"price\":\"0.776\",\"size\":\"46.3\"}],\"asks\":[{\"price\":\"0.999\",\"size\":\"102649.73\"},{\"price\":\"0.998\",\"size\":\"227.23\"},{\"price\":\"0.997\",\"size\":\"248.65\"},{\"price\":\"0.996\",\"size\":\"25\"},{\"price\":\"0.995\",\"size\":\"29.95\"},{\"price\":\"0.994\",\"size\":\"16.66\"},{\"price\":\"0.96\",\"size\":\"795.94\"},{\"price\":\"0.959\",\"size\":\"6.62\"},{\"price\":\"0.92\",\"size\":\"396.86\"},{\"price\":\"0.919\",\"size\":\"50\"},{\"price\":\"0.918\",\"size\":\"42.68\"},{\"price\":\"0.903\",\"size\":\"5332.66\"},{\"price\":\"0.902\",\"size\":\"30\"},{\"price\":\"0.869\",\"size\":\"45\"},{\"price\":\"0.858\",\"size\":\"32.41\"},{\"price\":\"0.843\",\"size\":\"80.1\"},{\"price\":\"0.826\",\"size\":\"26\"},{\"price\":\"0.821\",\"size\":\"30\"},{\"price\":\"0.817\",\"size\":\"306\"},{\"price\":\"0.812\",\"size\":\"239.67\"},{\"price\":\"0.811\",\"size\":\"30\"},{\"price\":\"0.81\",\"size\":\"30\"},{\"price\":\"0.808\",\"size\":\"60\"},{\"price\":\"0.806\",\"size\":\"18\"},{\"price\":\"0.805\",\"size\":\"165\"},{\"price\":\"0.802\",\"size\":\"30\"},{\"price\":\"0.798\",\"size\":\"14.82\"},{\"price\":\"0.793\",\"size\":\"22.06\"}],\"tick_size\":\"0.001\",\"event_type\":\"book\",\"last_trade_price\":\"0.776\"},{\"market\":\"0x43204573cf724eda06c520a42a7cb97df319cc27ed997be3b96ca74398ede87f\",\"asset_id\":\"37064221817179838225957455025143891294172126736355626367799841115771049178138\",\"timestamp\":\"1790267373615\",\"hash\":\"dcc95a125306359a9d66129aed1d4654776b3a31\",\"bids\":[{\"price\":\"0.02\",\"size\":\"127\"},{\"price\":\"0.2\",\"size\":\"310.87\"},{\"price\":\"0.21\",\"size\":\"9\"},{\"price\":\"0.65\",\"size\":\"54.22\"},{\"price\":\"0.66\",\"size\":\"10.6\"},{\"price\":\"0.79\",\"size\":\"100\"},{\"price\":\"0.83\",\"size\":\"302.34\"},{\"price\":\"0.84\",\"size\":\"8.33\"},{\"price\":\"0.85\",\"size\":\"594.7\"},{\"price\":\"0.86\",\"size\":\"350\"},{\"price\":\"0.88\",\"size\":\"150\"},{\"price\":\"0.91\",\"size\":\"599.98\"}],\"asks\":[{\"price\":\"0.99\",\"size\":\"5338.49\"},{\"price\":\"0.98\",\"size\":\"3221.86\"},{\"price\":\"0.97\",\"size\":\"1226.23\"},{\"price\":\"0.96\",\"size\":\"530\"},{\"price\":\"0.95\",\"size\":\"520.48\"},{\"price\":\"0.94\",\"size\":\"428.43\"},{\"price\":\"0.93\",\"size\":\"505\"},{\"price\":\"0.92\",\"size\":\"18.72\"}],\"tick_size\":\"0.01\",\"event_type\":\"book\",\"last_trade_price\":\"0.910\"},{\"market\":\"0x9397ebfe71585a4beb75b9562083f44d4335fa2858b7bc9a21d2e231ca4b454c\",\"asset_id\":\"51639815615464253806811879048250527088947940655978278010959957844379210492399\",\"timestamp\":\"1790267215568\",\"hash\":\"173a7c4307aa4172de2e314e3c54dae11e711672\",\"bids\":[{\"price\":\"0.01\",\"size\":\"19.19\"},{\"price\":\"0.02\",\"size\":\"10\"},{\"price\":\"0.03\",\"size\":\"6.66\"},{\"price\":\"0.09\",\"size\":\"50\"},{\"price\":\"0.25\",\"size\":\"20\"},{\"price\":\"0.4\",\"size\":\"200\"},{\"price\":\"0.41\",\"size\":\"38.69\"},{\"price\":\"0.52\",\"size\":\"38\"},{\"price\":\"0.62\",\"size\":\"10\"},{\"price\":\"0.63\",\"size\":\"2.29\"},{\"price\":\"0.64\",\"size\":\"55.66\"}],\"asks\":[{\"price\":\"0.99\",\"size\":\"1011.95\"},{\"price\":\"0.98\",\"size\":\"510\"},{\"price\":\"0.97\",\"size\":\"300\"},{\"price\":\"0.96\",\"size\":\"20\"},{\"price\":\"0.95\",\"size\":\"5.44\"},{\"price\":\"0.94\",\"size\":\"100\"},{\"price\":\"0.93\",\"size\":\"150\"},{\"price\":\"0.86\",\"size\":\"368.93\"},{\"price\":\"0.85\",\"size\":\"50\"},{\"price\":\"0.84\",\"size\":\"12.5\"},{\"price\":\"0.83\",\"size\":\"19.97\"}],\"tick_size\":\"0.01\",\"event_type\":\"book\",\"last_trade_price\":\"0.660\"},{\"market\":\"0xe98dcebda874fe4bddc1d55a86e2d44c59faad0a58b2d87f4e5c0962fdd6c953\",\"asset_id\":\"35420552064573957890054377289453060181883377972622279203964713014618594895479\",\"timestamp\":\"1790267371903\",\"hash\":\"722a8509f05ff55099289347dd7233d58e21224e\",\"bids\":[{\"price\":\"0.01\",\"size\":\"115009.42\"},{\"price\":\"0.02\",\"size\":\"20\"},{\"price\":\"0.03\",\"size\":\"79999.96\"},{\"price\":\"0.04\",\"size\":\"20\"},{\"price\":\"0.05\",\"size\":\"6.93\"},{\"price\":\"0.06\",\"size\":\"51249.98\"},{\"price\":\"0.11\",\"size\":\"30145.42\"},{\"price\":\"0.21\",\"size\":\"1714.28\"},{\"price\":\"0.32\",\"size\":\"1770.75\"},{\"price\":\"0.33\",\"size\":\"30\"},{\"price\":\"0.4\",\"size\":\"10\"},{\"price\":\"0.43\",\"size\":\"21.31\"},{\"price\":\"0.53\",\"size\":\"5.92\"},{\"price\":\"0.55\",\"size\":\"10\"},{\"price\":\"0.58\",\"size\":\"100\"},{\"price\":\"0.66\",\"size\":\"398.16\"},{\"price\":\"0.7\",\"size\":\"36\"},{\"price\":\"0.71\",\"size\":\"36.2\"},{\"price\":\"0.72\",\"size\":\"175.17\"},{\"price\":\"0.74\",\"size\":\"107.62\"},{\"price\":\"0.75\",\"size\":\"59.33\"},{\"price\":\"0.79\",\"size\":\"289.99\"},{\"price\":\"0.8\",\"size\":\"30\"}],\"asks\":[{\"price\":\"0.99\",\"size\":\"10046.21\"},{\"price\":\"0.98\",\"size\":\"820\"},{\"price\":\"0.97\",\"size\":\"116.66\"},{\"price\":\"0.96\",\"size\":\"7.22\"},{\"price\":\"0.92\",\"size\":\"20\"},{\"price\":\"0.91\",\"size\":\"55\"},{\"price\":\"0.9\",\"size\":\"174.66\"},{\"price\":\"0.89\",\"size\":\"60\"},{\"price\":\"0.87\",\"size\":\"10\"},{\"price\":\"0.86\",\"size\":\"5\"},{\"price\":\"0.85\",\"size\":\"55\"},{\"price\":\"0.84\",\"size\":\"15.43\"},{\"price\":\"0.83\",\"size\":\"131.99\"}],\"tick_size\":\"0.01\",\"event_type\":\"book\",\"last_trade_price\":\"0.820\"},{\"market\":\"0x3e685c84773bd018fff4219185b904b2ef194671320f47648121d07d2ae2cc17\",\"asset_id\":\"38577956202894813911522423295759441226459985692799781876715891336671282746369\",\"timestamp\":\"1790266870293\",\"hash\":\"b775a1deccc63b4ae341226a2e353376d445754a\",\"bids\":[{\"price\":\"0.001\",\"size\":\"3608.54\"},{\"price\":\"0.002\",\"size\":\"95.48\"},{\"price\":\"0.003\",\"size\":\"529.84\"},{\"price\":\"0.004\",\"size\":\"35.08\"},{\"price\":\"0.005\",\"size\":\"28.03\"},{\"price\":\"0.006\",\"size\":\"13.32\"},{\"price\":\"0.007\",\"size\":\"150\"},{\"price\":\"0.008\",\"size\":\"34.58\"},{\"price\":\"0.014\",\"size\":\"40\"},{\"price\":\"0.015\",\"size\":\"299\"},{\"price\":\"0.016\",\"size\":\"1885.56\"},{\"price\":\"0.017\",\"size\":\"158.99\"}],\"asks\":[{\"price\":\"0.999\",\"size\":\"4446.05\"},{\"price\":\"0.998\",\"size\":\"2234.94\"},{\"price\":\"0.997\",\"size\":\"11479.97\"},{\"price\":\"0.996\",\"size\":\"275\"},{\"price\":\"0.995\",\"size\":\"220\"},{\"price\":\"0.994\",\"size\":\"126.34\"},{\"price\":\"0.55\",\"size\":\"16.26\"},{\"price\":\"0.15\",\"size\":\"8.16\"},{\"price\":\"0.149\",\"size\":\"33.13\"},{\"price\":\"0.08\",\"size\":\"105\"},{\"price\":\"0.079\",\"size\":\"164\"},{\"price\":\"0.077\",\"size\":\"50\"},{\"price\":\"0.076\",\"size\":\"50\"},{\"price\":\"0.047\",\"size\":\"50\"},{\"price\":\"0.045\",\"size\":\"53\"},{\"price\":\"0.044\",\"size\":\"29.9\"},{\"price\":\"0.043\",\"size\":\"11.46\"}],\"tick_size\":\"0.001\",\"event_type\":\"book\",\"last_trade_price\":\"0.983\"},{\"market\":\"0xe98dcebda874fe4bddc1d55a86e2d44c59faad0a58b2d87f4e5c0962fdd6c953\",\"asset_id\":\"46636592743319383924405256772168587714503779223013840936712367884124732324660\",\"timestamp\":\"1790267371903\",\"hash\":\"fa7d9e3c37d6b8cf799fef0b8317903d54a6c682\",\"bids\":[{\"price\":\"0.01\",\"size\":\"10046.21\"},{\"price\":\"0.02\",\"size\":\"820\"},{\"price\":\"0.03\",\"size\":\"116.66\"},{\"price\":\"0.04\",\"size\":\"7.22\"},{\"price\":\"0.08\",\"size\":\"20\"},{\"price\":\"0.09\",\"size\":\"55\"},{\"price\":\"0.1\",\"size\":\"174.66\"},{\"price\":\"0.11\",\"size\":\"60\"},{\"price\":\"0.13\",\"size\":\"10\"},{\"price\":\"0.14\",\"size\":\"5\"},{\"price\":\"0.15\",\"size\":\"55\"},{\"price\":\"0.16\",\"size\":\"15.43\"},{\"price\":\"0.17\",\"size\":\"131.99\"}],\"asks\":[{\"price\":\"0.99\",\"size\":\"115009.42\"},{\"price\":\"0.98\",\"size\":\"20\"},{\"price\":\"0.97\",\"size\":\"79999.96\"},{\"price\":\"0.96\",\"size\":\"20\"},{\"price\":\"0.95\",\"size\":\"6.93\"},{\"price\":\"0.94\",\"size\":\"51249.98\"},{\"price\":\"0.89\",\"size\":\"30145.42\"},{\"price\":\"0.79\",\"size\":\"1714.28\"},{\"price\":\"0.68\",\"size\":\"1770.75\"},{\"price\":\"0.67\",\"size\":\"30\"},{\"price\":\"0.6\",\"size\":\"10\"},{\"price\":\"0.57\",\"size\":\"21.31\"},{\"price\":\"0.47\",\"size\":\"5.92\"},{\"price\":\"0.45\",\"size\":\"10\"},{\"price\":\"0.42\",\"size\":\"100\"},{\"price\":\"0.34\",\"size\":\"398.16\"},{\"price\":\"0.3\",\"size\":\"36\"},{\"price\":\"0.29\",\"size\":\"36.2\"},{\"price\":\"0.28\",\"size\":\"175.17\"},{\"price\":\"0.26\",\"size\":\"107.62\"},{\"price\":\"0.25\",\"size\":\"59.33\"},{\"price\":\"0.21\",\"size\":\"289.99\"},{\"price\":\"0.2\",\"size\":\"30\"}],\"tick_size\":\"0.01\",\"event_type\":\"book\",\"last_trade_price\":\"0.820\"},{\"market\":\"0x59cbdc98e569c31d3c33517131aa57a0a8d28e412df4a567d7df5b3ae9ec3de8\",\"asset_id\":\"6388191045056267170217957100365018215195736723213112943581350419506189056936\",\"timestamp\":\"1790267363323\",\"hash\":\"7289e7a595e82e37961d54f7f3c47dc0828da72f\",\"bids\":[{\"price\":\"0.01\",\"size\":\"9.29\"},{\"price\":\"0.04\",\"size\":\"51\"},{\"price\":\"0.05\",\"size\":\"6.96\"},{\"price\":\"0.6\",\"size\":\"800\"},{\"price\":\"0.75\",\"size\":\"1000\"},{\"price\":\"0.79\",\"size\":\"50\"},{\"price\":\"0.81\",\"size\":\"5\"},{\"price\":\"0.82\",\"size\":\"116.54\"}],\"asks\":[{\"price\":\"0.99\",\"size\":\"1117\"},{\"price\":\"0.98\",\"size\":\"35.28\"},{\"price\":\"0.97\",\"size\":\"116.66\"},{\"price\":\"0.96\",\"size\":\"115.88\"},{\"price\":\"0.94\",\"size\":\"166.6\"},{\"price\":\"0.89\",\"size\":\"26.19\"},{\"price\":\"0.88\",\"size\":\"71.66\"}],\"tick_size\":\"0.01\",\"event_type\":\"book\",\"last_trade_price\":\"0.870\"},{\"market\":\"0xd0e73ac0d00e8caf9cb7e74bcb024f94e57f34847f80ec2d4a0e3c57dbee7f19\",\"asset_id\":\"18110789428391406482230306080653613096309178214543987995456679527322864131310\",\"timestamp\":\"1790267336728\",\"hash\":\"79dd8c2648b279a9e3a33a38e6fe01e3bd6b42d8\",\"bids\":[{\"price\":\"0.01\",\"size\":\"7187.5\"},{\"price\":\"0.02\",\"size\":\"2201.88\"},{\"price\":\"0.03\",\"size\":\"1332.49\"},{\"price\":\"0.04\",\"size\":\"843.76\"},{\"price\":\"0.05\",\"size\":\"375\"},{\"price\":\"0.06\",\"size\":\"255.47\"},{\"price\":\"0.07\",\"size\":\"300\"},{\"price\":\"0.09\",\"size\":\"200\"},{\"price\":\"0.1\",\"size\":\"150\"},{\"price\":\"0.12\",\"size\":\"50\"},{\"price\":\"0.15\",\"size\":\"200\"},{\"price\":\"0.17\",\"size\":\"55\"},{\"price\":\"0.19\",\"size\":\"36.84\"},{\"price\":\"0.2\",\"size\":\"81.75\"},{\"price\":\"0.22\",\"size\":\"9.09\"}],\"asks\":[{\"price\":\"0.99\",\"size\":\"16.09\"},{\"price\":\"0.98\",\"size\":\"30\"},{\"price\":\"0.96\",\"size\":\"7\"},{\"price\":\"0.95\",\"size\":\"5.6\"},{\"price\":\"0.91\",\"size\":\"20\"},{\"price\":\"0.9\",\"size\":\"10\"},{\"price\":\"0.71\",\"size\":\"20\"},{\"price\":\"0.7\",\"size\":\"20\"},{\"price\":\"0.69\",\"size\":\"10.82\"},{\"price\":\"0.68\",\"size\":\"5\"},{\"price\":\"0.45\",\"size\":\"200\"}],\"tick_size\":\"0.01\",\"event_type\":\"book\",\"last_trade_price\":\"0.270\"},{\"market\":\"0x43204573cf724eda06c520a42a7cb97df319cc27ed997be3b96ca74398ede87f\",\"asset_id\":\"31627048520492227354616069874124458767757243686332730237616510640600462926383\",\"timestamp\":\"1790267373615\",\"hash\":\"61790c9a7a2623c333692cd88d7ecab1e84b1aec\",\"bids\":[{\"price\":\"0.01\",\"size\":\"5338.49\"},{\"price\":\"0.02\",\"size\":\"3221.86\"},{\"price\":\"0.03\",\"size\":\"1226.23\"},{\"price\":\"0.04\",\"size\":\"530\"},{\"price\":\"0.05\",\"size\":\"520.48\"},{\"price\":\"0.06\",\"size\":\"428.43\"},{\"price\":\"0.07\",\"size\":\"505\"},{\"price\":\"0.08\",\"size\":\"18.72\"}],\"asks\":[{\"price\":\"0.98\",\"size\":\"127\"},{\"price\":\"0.8\",\"size\":\"310.87\"},{\"price\":\"0.79\",\"size\":\"9\"},{\"price\":\"0.35\",\"size\":\"54.22\"},{\"price\":\"0.34\",\"size\":\"10.6\"},{\"price\":\"0.21\",\"size\":\"100\"},{\"price\":\"0.17\",\"size\":\"302.34\"},{\"price\":\"0.16\",\"size\":\"8.33\"},{\"price\":\"0.15\",\"size\":\"594.7\"},{\"price\":\"0.14\",\"size\":\"350\"},{\"price\":\"0.12\",\"size\":\"150\"},{\"price\":\"0.09\",\"size\":\"599.98\"}],\"tick_size\":\"0.01\",\"event_type\":\"book\",\"last_trade_price\":\"0.910\"},{\"market\":\"0xd3a3c1d537142ebc94ae25f7b268ce64e4e43e6452c5a912221d2e2744aeb312\",\"asset_id\":\"46094258080196889322046056727689179412841124675494563561748811364384667201787\",\"timestamp\":\"1790266966904\",\"hash\":\"deb98dbdd5d6af9ee2327543be4450244182ad9d\",\"bids\":[{\"price\":\"0.01\",\"size\":\"1000\"},{\"price\":\"0.02\",\"size\":\"20\"},{\"price\":\"0.03\",\"size\":\"13.06\"},{\"price\":\"0.11\",\"size\":\"2199.94\"},{\"price\":\"0.12\",\"size\":\"30\"},{\"price\":\"0.13\",\"size\":\"240\"},{\"price\":\"0.14\",\"size\":\"50\"},{\"price\":\"0.48\",\"size\":\"66.5\"},{\"price\":\"0.5\",\"size\":\"100\"},{\"price\":\"0.66\",\"size\":\"100\"},{\"price\":\"0.68\",\"size\":\"99.99\"},{\"price\":\"0.73\",\"size\":\"323.27\"},{\"price\":\"0.74\",\"size\":\"40\"},{\"price\":\"0.75\",\"size\":\"100\"}],\"asks\":[{\"price\":\"0.99\",\"size\":\"4149.25\"},{\"price\":\"0.98\",\"size\":\"2387.19\"},{\"price\":\"0.97\",\"size\":\"1216.6\"},{\"price\":\"0.96\",\"size\":\"726.86\"},{\"price\":\"0.95\",\"size\":\"5612.16\"},{\"price\":\"0.94\",\"size\":\"463.3\"},{\"price\":\"0.93\",\"size\":\"325.7\"},{\"price\":\"0.92\",\"size\":\"5\"},{\"price\":\"0.9\",\"size\":\"20\"},{\"price\":\"0.89\",\"size\":\"5.53\"},{\"price\":\"0.88\",\"size\":\"58.33\"},{\"price\":\"0.83\",\"size\":\"9931.31\"},{\"price\":\"0.81\",\"size\":\"4108.31\"},{\"price\":\"0.8\",\"size\":\"126.1\"}],\"tick_size\":\"0.01\",\"event_type\":\"book\",\"last_trade_price\":\"0.810\"},{\"market\":\"0xf31dc5f107bb556840fffa2bd0a503f891d82e61b0b7764e60cd92faec52a919\",\"asset_id\":\"16838256597398998291202588470738646116436652176742659727357735781336617089713\",\"timestamp\":\"1790267368547\",\"hash\":\"7ea967b4bbdd4c6d74d66f7e65f8c6b6a154e714\",\"bids\":[{\"price\":\"0.001\",\"size\":\"5455\"},{\"price\":\"0.002\",\"size\":\"2220\"},{\"price\":\"0.003\",\"size\":\"11479.97\"},{\"price\":\"0.004\",\"size\":\"275\"},{\"price\":\"0.005\",\"size\":\"220\"},{\"price\":\"0.013\",\"size\":\"41\"},{\"price\":\"0.25\",\"size\":\"25\"},{\"price\":\"0.437\",\"size\":\"11.44\"},{\"price\":\"0.5\",\"size\":\"125\"},{\"price\":\"0.501\",\"size\":\"17.96\"},{\"price\":\"0.502\",\"size\":\"17.92\"},{\"price\":\"0.83\",\"size\":\"200\"},{\"price\":\"0.837\",\"size\":\"30\"},{\"price\":\"0.838\",\"size\":\"146\"},{\"price\":\"0.84\",\"size\":\"1780.46\"},{\"price\":\"0.843\",\"size\":\"560\"},{\"price\":\"0.844\",\"size\":\"433.42\"},{\"price\":\"0.845\",\"size\":\"864.5\"},{\"price\":\"0.85\",\"size\":\"27.2\"}],\"asks\":[{\"price\":\"0.999\",\"size\":\"3009\"},{\"price\":\"0.998\",\"size\":\"420\"},{\"price\":\"0.997\",\"size\":\"679.65\"},{\"price\":\"0.996\",\"size\":\"408\"},{\"price\":\"0.995\",\"size\":\"1020\"},{\"price\":\"0.994\",\"size\":\"833.3\"},{\"price\":\"0.993\",\"size\":\"1714.2\"},{\"price\":\"0.992\",\"size\":\"625\"},{\"price\":\"0.991\",\"size\":\"555.5\"},{\"price\":\"0.99\",\"size\":\"920\"},{\"price\":\"0.989\",\"size\":\"454.5\"},{\"price\":\"0.988\",\"size\":\"616.6\"},{\"price\":\"0.983\",\"size\":\"100\"},{\"price\":\"0.978\",\"size\":\"100\"},{\"price\":\"0.977\",\"size\":\"400\"},{\"price\":\"0.973\",\"size\":\"150.85\"},{\"price\":\"0.97\",\"size\":\"500\"},{\"price\":\"0.968\",\"size\":\"100\"},{\"price\":\"0.966\",\"size\":\"300\"},{\"price\":\"0.965\",\"size\":\"30\"},{\"price\":\"0.963\",\"size\":\"67.16\"},{\"price\":\"0.962\",\"size\":\"122.1\"},{\"price\":\"0.961\",\"size\":\"300\"},{\"price\":\"0.96\",\"size\":\"242\"},{\"price\":\"0.958\",\"size\":\"287.04\"},{\"price\":\"0.957\",\"size\":\"52.95\"},{\"price\":\"0.955\",\"size\":\"20\"},{\"price\":\"0.953\",\"size\":\"74.46\"},{\"price\":\"0.932\",\"size\":\"5\"},{\"price\":\"0.93\",\"size\":\"161.9\"},{\"price\":\"0.929\",\"size\":\"50\"},{\"price\":\"0.9\",\"size\":\"101\"},{\"price\":\"0.898\",\"size\":\"5\"},{\"price\":\"0.886\",\"size\":\"600\"},{\"price\":\"0.885\",\"size\":\"192.33\"},{\"price\":\"0.884\",\"size\":\"202\"},{\"price\":\"0.883\",\"size\":\"664.5\"},{\"price\":\"0.882\",\"size\":\"200.1\"},{\"price\":\"0.879\",\"size\":\"116\"},{\"price\":\"0.878\",\"size\":\"30\"}],\"tick_size\":\"0.001\",\"event_type\":\"book\",\"last_trade_price\":\"0.850\"},{\"market\":\"0xc48e17e33742004e4ec5d3386d05f7d723f1c2da37b5cbc56e9ce432e13d8ed4\",\"asset_id\":\"50067946737985819644638241783771238619616055560007143911749636220745966692358\",\"timestamp\":\"1790267353913\",\"hash\":\"fb8ae41f1201ce85f3c93b89f961e7f4e6d945cd\",\"bids\":[{\"price\":\"0.01\",\"size\":\"320875\"},{\"price\":\"0.02\",\"size\":\"12588.76\"},{\"price\":\"0.03\",\"size\":\"11437.49\"},{\"price\":\"0.04\",\"size\":\"1468.76\"},{\"price\":\"0.05\",\"size\":\"1725\"},{\"price\":\"0.06\",\"size\":\"500\"},{\"price\":\"0.07\",\"size\":\"770\"},{\"price\":\"0.08\",\"size\":\"500\"},{\"price\":\"0.1\",\"size\":\"250\"},{\"price\":\"0.11\",\"size\":\"750\"},{\"price\":\"0.2\",\"size\":\"250\"},{\"price\":\"0.3\",\"size\":\"1000\"},{\"price\":\"0.31\",\"size\":\"50\"},{\"price\":\"0.4\",\"size\":\"1000\"},{\"price\":\"0.41\",\"size\":\"620\"},{\"price\":\"0.42\",\"size\":\"16.66\"},{\"price\":\"0.54\",\"size\":\"120\"},{\"price\":\"0.55\",\"size\":\"2382.88\"},{\"price\":\"0.56\",\"size\":\"2313.21\"},{\"price\":\"0.57\",\"size\":\"5\"}],\"asks\":[{\"price\":\"0.99\",\"size\":\"6.39\"},{\"price\":\"0.98\",\"size\":\"527\"},{\"price\":\"0.92\",\"size\":\"50\"},{\"price\":\"0.87\",\"size\":\"46.4\"},{\"price\":\"0.82\",\"size\":\"30\"},{\"price\":\"0.79\",\"size\":\"300\"},{\"price\":\"0.78\",\"size\":\"50\"},{\"price\":\"0.75\",\"size\":\"20\"},{\"price\":\"0.74\",\"size\":\"500\"},{\"price\":\"0.71\",\"size\":\"500\"},{\"price\":\"0.68\",\"size\":\"489.69\"},{\"price\":\"0.67\",\"size\":\"884.67\"},{\"price\":\"0.66\",\"size\":\"20.58\"},{\"price\":\"0.65\",\"size\":\"300\"},{\"price\":\"0.64\",\"size\":\"181.29\"},{\"price\":\"0.63\",\"size\":\"50\"},{\"price\":\"0.62\",\"size\":\"5\"},{\"price\":\"0.6\",\"size\":\"750.03\"},{\"price\":\"0.59\",\"size\":\"106.33\"}],\"tick_size\":\"0.01\",\"event_type\":\"book\",\"last_trade_price\":\"0.420\"},{\"market\":\"0xd0e73ac0d00e8caf9cb7e74bcb024f94e57f34847f80ec2d4a0e3c57dbee7f19\",\"asset_id\":\"62313236991955111601391854345293627475130543547194366725001724474611291151185\",\"timestamp\":\"1790267336728\",\"hash\":\"3a72e232db0e80828ff4c6f854c8deca04c2c1bf\",\"bids\":[{\"price\":\"0.01\",\"size\":\"16.09\"},{\"price\":\"0.02\",\"size\":\"30\"},{\"price\":\"0.04\",\"size\":\"7\"},{\"price\":\"0.05\",\"size\":\"5.6\"},{\"price\":\"0.09\",\"size\":\"20\"},{\"price\":\"0.1\",\"size\":\"10\"},{\"price\":\"0.29\",\"size\":\"20\"},{\"price\":\"0.3\",\"size\":\"20\"},{\"price\":\"0.31\",\"size\":\"10.82\"},{\"price\":\"0.32\",\"size\":\"5\"},{\"price\":\"0.55\",\"size\":\"200\"}],\"asks\":[{\"price\":\"0.99\",\"size\":\"7187.5\"},{\"price\":\"0.98\",\"size\":\"2201.88\"},{\"price\":\"0.97\",\"size\":\"1332.49\"},{\"price\":\"0.96\",\"size\":\"843.76\"},{\"price\":\"0.95\",\"size\":\"375\"},{\"price\":\"0.94\",\"size\":\"255.47\"},{\"price\":\"0.93\",\"size\":\"300\"},{\"price\":\"0.91\",\"size\":\"200\"},{\"price\":\"0.9\",\"size\":\"150\"},{\"price\":\"0.88\",\"size\":\"50\"},{\"price\":\"0.85\",\"size\":\"200\"},{\"price\":\"0.83\",\"size\":\"55\"},{\"price\":\"0.81\",\"size\":\"36.84\"},{\"price\":\"0.8\",\"size\":\"81.75\"},{\"price\":\"0.78\",\"size\":\"9.09\"}],\"tick_size\":\"0.01\",\"event_type\":\"book\",\"last_trade_price\":\"0.270\"},{\"market\":\"0xf31dc5f107bb556840fffa2bd0a503f891d82e61b0b7764e60cd92faec52a919\",\"asset_id\":\"82810327953012498612382200175108254608097289209592945267796930988226249448409\",\"timestamp\":\"1790267368547\",\"hash\":\"4f4087e79787f9b2e5b1e4a7e41e7cb707c7f26a\",\"bids\":[{\"price\":\"0.001\",\"size\":\"3009\"},{\"price\":\"0.002\",\"size\":\"420\"},{\"price\":\"0.003\",\"size\":\"679.65\"},{\"price\":\"0.004\",\"size\":\"408\"},{\"price\":\"0.005\",\"size\":\"1020\"},{\"price\":\"0.006\",\"size\":\"833.3\"},{\"price\":\"0.007\",\"size\":\"1714.2\"},{\"price\":\"0.008\",\"size\":\"625\"},{\"price\":\"0.009\",\"size\":\"555.5\"},{\"price\":\"0.01\",\"size\":\"920\"},{\"price\":\"0.011\",\"size\":\"454.5\"},{\"price\":\"0.012\",\"size\":\"616.6\"},{\"price\":\"0.017\",\"size\":\"100\"},{\"price\":\"0.022\",\"size\":\"100\"},{\"price\":\"0.023\",\"size\":\"400\"},{\"price\":\"0.027\",\"size\":\"150.85\"},{\"price\":\"0.03\",\"size\":\"500\"},{\"price\":\"0.032\",\"size\":\"100\"},{\"price\":\"0.034\",\"size\":\"300\"},{\"price\":\"0.035\",\"size\":\"30\"},{\"price\":\"0.037\",\"size\":\"67.16\"},{\"price\":\"0.038\",\"size\":\"122.1\"},{\"price\":\"0.039\",\"size\":\"300\"},{\"price\":\"0.04\",\"size\":\"242\"},{\"price\":\"0.042\",\"size\":\"287.04\"},{\"price\":\"0.043\",\"size\":\"52.95\"},{\"price\":\"0.045\",\"size\":\"20\"},{\"price\":\"0.047\",\"size\":\"74.46\"},{\"price\":\"0.068\",\"size\":\"5\"},{\"price\":\"0.07\",\"size\":\"161.9\"},{\"price\":\"0.071\",\"size\":\"50\"},{\"price\":\"0.1\",\"size\":\"101\"},{\"price\":\"0.102\",\"size\":\"5\"},{\"price\":\"0.114\",\"size\":\"600\"},{\"price\":\"0.115\",\"size\":\"192.33\"},{\"price\":\"0.116\",\"size\":\"202\"},{\"price\":\"0.117\",\"size\":\"664.5\"},{\"price\":\"0.118\",\"size\":\"200.1\"},{\"price\":\"0.121\",\"size\":\"116\"},{\"price\":\"0.122\",\"size\":\"30\"}],\"asks\":[{\"price\":\"0.999\",\"size\":\"5455\"},{\"price\":\"0.998\",\"size\":\"2220\"},{\"price\":\"0.997\",\"size\":\"11479.97\"},{\"price\":\"0.996\",\"size\":\"275\"},{\"price\":\"0.995\",\"size\":\"220\"},{\"price\":\"0.987\",\"size\":\"41\"},{\"price\":\"0.75\",\"size\":\"25\"},{\"price\":\"0.563\",\"size\":\"11.44\"},{\"price\":\"0.5\",\"size\":\"125\"},{\"price\":\"0.499\",\"size\":\"17.96\"},{\"price\":\"0.498\",\"size\":\"17.92\"},{\"price\":\"0.17\",\"size\":\"200\"},{\"price\":\"0.163\",\"size\":\"30\"},{\"price\":\"0.162\",\"size\":\"146\"},{\"price\":\"0.16\",\"size\":\"1780.46\"},{\"price\":\"0.157\",\"size\":\"560\"},{\"price\":\"0.156\",\"size\":\"433.42\"},{\"price\":\"0.155\",\"size\":\"864.5\"},{\"price\":\"0.15\",\"size\":\"27.2\"}],\"tick_size\":\"0.001\",\"event_type\":\"book\",\"last_trade_price\":\"0.850\"},{\"market\":\"0x9397ebfe71585a4beb75b9562083f44d4335fa2858b7bc9a21d2e231ca4b454c\",\"asset_id\":\"92063509161371023588356720867210063473058158748167650409901048666263049686317\",\"timestamp\":\"1790267215568\",\"hash\":\"e886106b09d02abc838e4e0019fa1023ffe4204b\",\"bids\":[{\"price\":\"0.01\",\"size\":\"1011.95\"},{\"price\":\"0.02\",\"size\":\"510\"},{\"price\":\"0.03\",\"size\":\"300\"},{\"price\":\"0.04\",\"size\":\"20\"},{\"price\":\"0.05\",\"size\":\"5.44\"},{\"price\":\"0.06\",\"size\":\"100\"},{\"price\":\"0.07\",\"size\":\"150\"},{\"price\":\"0.14\",\"size\":\"368.93\"},{\"price\":\"0.15\",\"size\":\"50\"},{\"price\":\"0.16\",\"size\":\"12.5\"},{\"price\":\"0.17\",\"size\":\"19.97\"}],\"asks\":[{\"price\":\"0.99\",\"size\":\"19.19\"},{\"price\":\"0.98\",\"size\":\"10\"},{\"price\":\"0.97\",\"size\":\"6.66\"},{\"price\":\"0.91\",\"size\":\"50\"},{\"price\":\"0.75\",\"size\":\"20\"},{\"price\":\"0.6\",\"size\":\"200\"},{\"price\":\"0.59\",\"size\":\"38.69\"},{\"price\":\"0.48\",\"size\":\"38\"},{\"price\":\"0.38\",\"size\":\"10\"},{\"price\":\"0.37\",\"size\":\"2.29\"},{\"price\":\"0.36\",\"size\":\"55.66\"}],\"tick_size\":\"0.01\",\"event_type\":\"book\",\"last_trade_price\":\"0.660\"},{\"market\":\"0x12ed4858fd4aa92e1a644c74273ca76f49735c114d6833f8a3edef4f19e5ebff\",\"asset_id\":\"35599907049186982879557420969598528789434547136942253652554709047485665633870\",\"timestamp\":\"1790267378390\",\"hash\":\"3186624ddd90c0cbd180a76243f9770d770efddd\",\"bids\":[{\"price\":\"0.01\",\"size\":\"7199.64\"},{\"price\":\"0.02\",\"size\":\"2176.26\"},{\"price\":\"0.03\",\"size\":\"1312.49\"},{\"price\":\"0.04\",\"size\":\"863.76\"},{\"price\":\"0.05\",\"size\":\"381.39\"},{\"price\":\"0.06\",\"size\":\"250\"},{\"price\":\"0.08\",\"size\":\"300\"},{\"price\":\"0.11\",\"size\":\"100\"},{\"price\":\"0.14\",\"size\":\"300\"},{\"price\":\"0.15\",\"size\":\"180\"},{\"price\":\"0.2\",\"size\":\"100\"},{\"price\":\"0.21\",\"size\":\"100\"},{\"price\":\"0.23\",\"size\":\"30.43\"},{\"price\":\"0.24\",\"size\":\"13.32\"},{\"price\":\"0.27\",\"size\":\"25\"},{\"price\":\"0.28\",\"size\":\"7.14\"},{\"price\":\"0.32\",\"size\":\"10\"},{\"price\":\"0.33\",\"size\":\"20\"},{\"price\":\"0.34\",\"size\":\"5.02\"}],\"asks\":[{\"price\":\"0.99\",\"size\":\"44.1\"},{\"price\":\"0.84\",\"size\":\"87.17\"},{\"price\":\"0.83\",\"size\":\"52\"},{\"price\":\"0.5\",\"size\":\"24.97\"},{\"price\":\"0.45\",\"size\":\"36.75\"},{\"price\":\"0.43\",\"size\":\"10\"},{\"price\":\"0.41\",\"size\":\"111\"},{\"price\":\"0.4\",\"size\":\"67.34\"},{\"price\":\"0.39\",\"size\":\"30\"}],\"tick_size\":\"0.01\",\"event_type\":\"book\",\"last_trade_price\":\"0.600\"},{\"market\":\"0x12ed4858fd4aa92e1a644c74273ca76f49735c114d6833f8a3edef4f19e5ebff\",\"asset_id\":\"18054759644013870900749170809345467324611742242067616964612696305379357034954\",\"timestamp\":\"1790267378390\",\"hash\":\"f598a79058977ba620ec15d209857c739706b6aa\",\"bids\":[{\"price\":\"0.01\",\"size\":\"44.1\"},{\"price\":\"0.16\",\"size\":\"87.17\"},{\"price\":\"0.17\",\"size\":\"52\"},{\"price\":\"0.5\",\"size\":\"24.97\"},{\"price\":\"0.55\",\"size\":\"36.75\"},{\"price\":\"0.57\",\"size\":\"10\"},{\"price\":\"0.59\",\"size\":\"111\"},{\"price\":\"0.6\",\"size\":\"67.34\"},{\"price\":\"0.61\",\"size\":\"30\"}],\"asks\":[{\"price\":\"0.99\",\"size\":\"7199.64\"},{\"price\":\"0.98\",\"size\":\"2176.26\"},{\"price\":\"0.97\",\"size\":\"1312.49\"},{\"price\":\"0.96\",\"size\":\"863.76\"},{\"price\":\"0.95\",\"size\":\"381.39\"},{\"price\":\"0.94\",\"size\":\"250\"},{\"price\":\"0.92\",\"size\":\"300\"},{\"price\":\"0.89\",\"size\":\"100\"},{\"price\":\"0.86\",\"size\":\"300\"},{\"price\":\"0.85\",\"size\":\"180\"},{\"price\":\"0.8\",\"size\":\"100\"},{\"price\":\"0.79\",\"size\":\"100\"},{\"price\":\"0.77\",\"size\":\"30.43\"},{\"price\":\"0.76\",\"size\":\"13.32\"},{\"price\":\"0.73\",\"size\":\"25\"},{\"price\":\"0.72\",\"size\":\"7.14\"},{\"price\":\"0.68\",\"size\":\"10\"},{\"price\":\"0.67\",\"size\":\"20\"},{\"price\":\"0.66\",\"size\":\"5.02\"}],\"tick_size\":\"0.01\",\"event_type\":\"book\",\"last_trade_price\":\"0.600\"},{\"market\":\"0x3e685c84773bd018fff4219185b904b2ef194671320f47648121d07d2ae2cc17\",\"asset_id\":\"31239779091556707685216681559343622450417987997527657281659332570836878668226\",\"timestamp\":\"1790266870293\",\"hash\":\"046057d7a3289a04c64e9fd2c73a7fd98a85dabd\",\"bids\":[{\"price\":\"0.001\",\"size\":\"4446.05\"},{\"price\":\"0.002\",\"size\":\"2234.94\"},{\"price\":\"0.003\",\"size\":\"11479.97\"},{\"price\":\"0.004\",\"size\":\"275\"},{\"price\":\"0.005\",\"size\":\"220\"},{\"price\":\"0.006\",\"size\":\"126.34\"},{\"price\":\"0.45\",\"size\":\"16.26\"},{\"price\":\"0.85\",\"size\":\"8.16\"},{\"price\":\"0.851\",\"size\":\"33.13\"},{\"price\":\"0.92\",\"size\":\"105\"},{\"price\":\"0.921\",\"size\":\"164\"},{\"price\":\"0.923\",\"size\":\"50\"},{\"price\":\"0.924\",\"size\":\"50\"},{\"price\":\"0.953\",\"size\":\"50\"},{\"price\":\"0.955\",\"size\":\"53\"},{\"price\":\"0.956\",\"size\":\"29.9\"},{\"price\":\"0.957\",\"size\":\"11.46\"}],\"asks\":[{\"price\":\"0.999\",\"size\":\"3608.54\"},{\"price\":\"0.998\",\"size\":\"95.48\"},{\"price\":\"0.997\",\"size\":\"529.84\"},{\"price\":\"0.996\",\"size\":\"35.08\"},{\"price\":\"0.995\",\"size\":\"28.03\"},{\"price\":\"0.994\",\"size\":\"13.32\"},{\"price\":\"0.993\",\"size\":\"150\"},{\"price\":\"0.992\",\"size\":\"34.58\"},{\"price\":\"0.986\",\"size\":\"40\"},{\"price\":\"0.985\",\"size\":\"299\"},{\"price\":\"0.984\",\"size\":\"1885.56\"},{\"price\":\"0.983\",\"size\":\"158.99\"}],\"tick_size\":\"0.001\",\"event_type\":\"book\",\"last_trade_price\":\"0.983\"},{\"market\":\"0x77a4012e47d506eee2a992032c11dab236bb56cac17a994bc2db3f7467cd97d1\",\"asset_id\":\"15390584632108771016450588704807221443840679092964759511537241445184106992060\",\"timestamp\":\"1790267327173\",\"hash\":\"f86302d3ed4709be2c1bded0db6643a775166c1e\",\"bids\":[{\"price\":\"0.001\",\"size\":\"102649.73\"},{\"price\":\"0.002\",\"size\":\"227.23\"},{\"price\":\"0.003\",\"size\":\"248.65\"},{\"price\":\"0.004\",\"size\":\"25\"},{\"price\":\"0.005\",\"size\":\"29.95\"},{\"price\":\"0.006\",\"size\":\"16.66\"},{\"price\":\"0.04\",\"size\":\"795.94\"},{\"price\":\"0.041\",\"size\":\"6.62\"},{\"price\":\"0.08\",\"size\":\"396.86\"},{\"price\":\"0.081\",\"size\":\"50\"},{\"price\":\"0.082\",\"size\":\"42.68\"},{\"price\":\"0.097\",\"size\":\"5332.66\"},{\"price\":\"0.098\",\"size\":\"30\"},{\"price\":\"0.131\",\"size\":\"45\"},{\"price\":\"0.142\",\"size\":\"32.41\"},{\"price\":\"0.157\",\"size\":\"80.1\"},{\"price\":\"0.174\",\"size\":\"26\"},{\"price\":\"0.179\",\"size\":\"30\"},{\"price\":\"0.183\",\"size\":\"306\"},{\"price\":\"0.188\",\"size\":\"239.67\"},{\"price\":\"0.189\",\"size\":\"30\"},{\"price\":\"0.19\",\"size\":\"30\"},{\"price\":\"0.192\",\"size\":\"60\"},{\"price\":\"0.194\",\"size\":\"18\"},{\"price\":\"0.195\",\"size\":\"165\"},{\"price\":\"0.198\",\"size\":\"30\"},{\"price\":\"0.202\",\"size\":\"14.82\"},{\"price\":\"0.207\",\"size\":\"22.06\"}],\"asks\":[{\"price\":\"0.999\",\"size\":\"9136.18\"},{\"price\":\"0.998\",\"size\":\"720\"},{\"price\":\"0.997\",\"size\":\"486.54\"},{\"price\":\"0.996\",\"size\":\"275\"},{\"price\":\"0.995\",\"size\":\"220\"},{\"price\":\"0.99\",\"size\":\"115123.31\"},{\"price\":\"0.989\",\"size\":\"7.39\"},{\"price\":\"0.98\",\"size\":\"102500\"},{\"price\":\"0.97\",\"size\":\"5000\"},{\"price\":\"0.94\",\"size\":\"3333.33\"},{\"price\":\"0.939\",\"size\":\"5.46\"},{\"price\":\"0.908\",\"size\":\"20\"},{\"price\":\"0.9\",\"size\":\"31160\"},{\"price\":\"0.849\",\"size\":\"22847.62\"},{\"price\":\"0.82\",\"size\":\"1666.66\"},{\"price\":\"0.8\",\"size\":\"90\"},{\"price\":\"0.78\",\"size\":\"1363.63\"},{\"price\":\"0.74\",\"size\":\"53.06\"},{\"price\":\"0.7\",\"size\":\"10866.66\"},{\"price\":\"0.671\",\"size\":\"1863.82\"},{\"price\":\"0.492\",\"size\":\"200\"},{\"price\":\"0.49\",\"size\":\"20\"},{\"price\":\"0.45\",\"size\":\"20\"},{\"price\":\"0.373\",\"size\":\"294.33\"},{\"price\":\"0.369\",\"size\":\"500\"},{\"price\":\"0.364\",\"size\":\"300\"},{\"price\":\"0.363\",\"size\":\"40.34\"},{\"price\":\"0.36\",\"size\":\"30\"},{\"price\":\"0.277\",\"size\":\"222.4\"},{\"price\":\"0.276\",\"size\":\"9.66\"},{\"price\":\"0.263\",\"size\":\"31.02\"},{\"price\":\"0.262\",\"size\":\"30.99\"},{\"price\":\"0.261\",\"size\":\"30.95\"},{\"price\":\"0.26\",\"size\":\"30.92\"},{\"price\":\"0.259\",\"size\":\"30.89\"},{\"price\":\"0.258\",\"size\":\"30.86\"},{\"price\":\"0.257\",\"size\":\"30.83\"},{\"price\":\"0.256\",\"size\":\"30.8\"},{\"price\":\"0.255\",\"size\":\"30.76\"},{\"price\":\"0.254\",\"size\":\"30.73\"},{\"price\":\"0.252\",\"size\":\"31.98\"},{\"price\":\"0.251\",\"size\":\"31.94\"},{\"price\":\"0.233\",\"size\":\"100\"},{\"price\":\"0.232\",\"size\":\"176.46\"},{\"price\":\"0.231\",\"size\":\"456.44\"},{\"price\":\"0.229\",\"size\":\"30\"},{\"price\":\"0.224\",\"size\":\"46.3\"}],\"tick_size\":\"0.001\",\"event_type\":\"book\",\"last_trade_price\":\"0.776\"},{\"market\":\"0xd3a3c1d537142ebc94ae25f7b268ce64e4e43e6452c5a912221d2e2744aeb312\",\"asset_id\":\"23979773390611496299652546131606735686099256186322678196712320732715801255871\",\"timestamp\":\"1790266966904\",\"hash\":\"4aca0673a3f00a730030079ddc8d5f7c2a44815d\",\"bids\":[{\"price\":\"0.01\",\"size\":\"4149.25\"},{\"price\":\"0.02\",\"size\":\"2387.19\"},{\"price\":\"0.03\",\"size\":\"1216.6\"},{\"price\":\"0.04\",\"size\":\"726.86\"},{\"price\":\"0.05\",\"size\":\"5612.16\"},{\"price\":\"0.06\",\"size\":\"463.3\"},{\"price\":\"0.07\",\"size\":\"325.7\"},{\"price\":\"0.08\",\"size\":\"5\"},{\"price\":\"0.1\",\"size\":\"20\"},{\"price\":\"0.11\",\"size\":\"5.53\"},{\"price\":\"0.12\",\"size\":\"58.33\"},{\"price\":\"0.17\",\"size\":\"9931.31\"},{\"price\":\"0.19\",\"size\":\"4108.31\"},{\"price\":\"0.2\",\"size\":\"126.1\"}],\"asks\":[{\"price\":\"0.99\",\"size\":\"1000\"},{\"price\":\"0.98\",\"size\":\"20\"},{\"price\":\"0.97\",\"size\":\"13.06\"},{\"price\":\"0.89\",\"size\":\"2199.94\"},{\"price\":\"0.88\",\"size\":\"30\"},{\"price\":\"0.87\",\"size\":\"240\"},{\"price\":\"0.86\",\"size\":\"50\"},{\"price\":\"0.52\",\"size\":\"66.5\"},{\"price\":\"0.5\",\"size\":\"100\"},{\"price\":\"0.34\",\"size\":\"100\"},{\"price\":\"0.32\",\"size\":\"99.99\"},{\"price\":\"0.27\",\"size\":\"323.27\"},{\"price\":\"0.26\",\"size\":\"40\"},{\"price\":\"0.25\",\"size\":\"100\"}],\"tick_size\":\"0.01\",\"event_type\":\"book\",\"last_trade_price\":\"0.810\"},{\"market\":\"0x0cb565e64adf218ced0640e9e6190b36e5cf18870b7b7254c792a8cd90136cbc\",\"asset_id\":\"51934659473229616633979925778638522086339145112323753438764061374489696583019\",\"timestamp\":\"1790266470818\",\"hash\":\"0d359855b0afac2d8d792a9a63e58cd1823df0d0\",\"bids\":[{\"price\":\"0.01\",\"size\":\"23\"},{\"price\":\"0.05\",\"size\":\"37000\"},{\"price\":\"0.06\",\"size\":\"9.23\"},{\"price\":\"0.09\",\"size\":\"12444.44\"},{\"price\":\"0.14\",\"size\":\"7999.99\"},{\"price\":\"0.17\",\"size\":\"6.37\"},{\"price\":\"0.19\",\"size\":\"5473.68\"},{\"price\":\"0.24\",\"size\":\"3666.66\"},{\"price\":\"0.29\",\"size\":\"2758.62\"},{\"price\":\"0.31\",\"size\":\"31.75\"},{\"price\":\"0.33\",\"size\":\"2424.24\"},{\"price\":\"0.35\",\"size\":\"1000\"},{\"price\":\"0.36\",\"size\":\"6.37\"},{\"price\":\"0.38\",\"size\":\"1684.21\"},{\"price\":\"0.39\",\"size\":\"1000\"},{\"price\":\"0.4\",\"size\":\"53.21\"},{\"price\":\"0.65\",\"size\":\"5\"},{\"price\":\"0.66\",\"size\":\"12.73\"},{\"price\":\"0.91\",\"size\":\"63.21\"}],\"asks\":[{\"price\":\"0.99\",\"size\":\"3073.86\"},{\"price\":\"0.98\",\"size\":\"1437.36\"},{\"price\":\"0.97\",\"size\":\"500\"},{\"price\":\"0.96\",\"size\":\"332.4\"},{\"price\":\"0.95\",\"size\":\"20\"}],\"tick_size\":\"0.01\",\"event_type\":\"book\",\"last_trade_price\":\"0.910\"},{\"market\":\"0x0cb565e64adf218ced0640e9e6190b36e5cf18870b7b7254c792a8cd90136cbc\",\"asset_id\":\"74107397498677748358788981338872770990986891527997529881194144858053459361311\",\"timestamp\":\"1790266470818\",\"hash\":\"82081ad0ab3befd447d3f774f138eb274bb59a91\",\"bids\":[{\"price\":\"0.01\",\"size\":\"3073.86\"},{\"price\":\"0.02\",\"size\":\"1437.36\"},{\"price\":\"0.03\",\"size\":\"500\"},{\"price\":\"0.04\",\"size\":\"332.4\"},{\"price\":\"0.05\",\"size\":\"20\"}],\"asks\":[{\"price\":\"0.99\",\"size\":\"23\"},{\"price\":\"0.95\",\"size\":\"37000\"},{\"price\":\"0.94\",\"size\":\"9.23\"},{\"price\":\"0.91\",\"size\":\"12444.44\"},{\"price\":\"0.86\",\"size\":\"7999.99\"},{\"price\":\"0.83\",\"size\":\"6.37\"},{\"price\":\"0.81\",\"size\":\"5473.68\"},{\"price\":\"0.76\",\"size\":\"3666.66\"},{\"price\":\"0.71\",\"size\":\"2758.62\"},{\"price\":\"0.69\",\"size\":\"31.75\"},{\"price\":\"0.67\",\"size\":\"2424.24\"},{\"price\":\"0.65\",\"size\":\"1000\"},{\"price\":\"0.64\",\"size\":\"6.37\"},{\"price\":\"0.62\",\"size\":\"1684.21\"},{\"price\":\"0.61\",\"size\":\"1000\"},{\"price\":\"0.6\",\"size\":\"53.21\"},{\"price\":\"0.35\",\"size\":\"5\"},{\"price\":\"0.34\",\"size\":\"12.73\"},{\"price\":\"0.09\",\"size\":\"63.21\"}],\"tick_size\":\"0.01\",\"event_type\":\"book\",\"last_trade_price\":\"0.910\"},{\"market\":\"0x9027a12cbbf78e9bff760402ab106732fa5a4af2002e4f48e5cc406ac1447800\",\"asset_id\":\"38175379283808228327034811002747441529537312086974479792536732908990840238523\",\"timestamp\":\"1790267321830\",\"hash\":\"83f1a5cb47f15d2878f70336567d4a2b203cb1cf\",\"bids\":[{\"price\":\"0.01\",\"size\":\"12005.14\"},{\"price\":\"0.02\",\"size\":\"276.54\"},{\"price\":\"0.03\",\"size\":\"166.6\"},{\"price\":\"0.04\",\"size\":\"925\"},{\"price\":\"0.05\",\"size\":\"135.17\"},{\"price\":\"0.06\",\"size\":\"535.87\"},{\"price\":\"0.07\",\"size\":\"71.4\"},{\"price\":\"0.08\",\"size\":\"443.03\"},{\"price\":\"0.09\",\"size\":\"40\"},{\"price\":\"0.1\",\"size\":\"30\"},{\"price\":\"0.11\",\"size\":\"55\"},{\"price\":\"0.12\",\"size\":\"29.93\"},{\"price\":\"0.13\",\"size\":\"233.78\"},{\"price\":\"0.14\",\"size\":\"315.02\"},{\"price\":\"0.15\",\"size\":\"1607.69\"},{\"price\":\"0.16\",\"size\":\"269.97\"},{\"price\":\"0.17\",\"size\":\"165.96\"},{\"price\":\"0.19\",\"size\":\"27\"},{\"price\":\"0.2\",\"size\":\"71.03\"}],\"asks\":[{\"price\":\"0.99\",\"size\":\"115262.9\"},{\"price\":\"0.98\",\"size\":\"102500\"},{\"price\":\"0.97\",\"size\":\"5000\"},{\"price\":\"0.96\",\"size\":\"9.13\"},{\"price\":\"0.93\",\"size\":\"11857.14\"},{\"price\":\"0.9\",\"size\":\"31211\"},{\"price\":\"0.86\",\"size\":\"1785.71\"},{\"price\":\"0.8\",\"size\":\"17900\"},{\"price\":\"0.78\",\"size\":\"1363.63\"},{\"price\":\"0.73\",\"size\":\"30\"},{\"price\":\"0.7\",\"size\":\"10866.66\"},{\"price\":\"0.69\",\"size\":\"10483.85\"},{\"price\":\"0.68\",\"size\":\"4500\"},{\"price\":\"0.66\",\"size\":\"800\"},{\"price\":\"0.65\",\"size\":\"4500\"},{\"price\":\"0.64\",\"size\":\"50\"},{\"price\":\"0.62\",\"size\":\"50\"},{\"price\":\"0.59\",\"size\":\"305.58\"},{\"price\":\"0.51\",\"size\":\"100\"},{\"price\":\"0.5\",\"size\":\"122.01\"},{\"price\":\"0.48\",\"size\":\"100\"},{\"price\":\"0.34\",\"size\":\"15\"},{\"price\":\"0.32\",\"size\":\"499.99\"},{\"price\":\"0.31\",\"size\":\"5.97\"},{\"price\":\"0.3\",\"size\":\"32.46\"},{\"price\":\"0.29\",\"size\":\"30\"},{\"price\":\"0.28\",\"size\":\"30\"},{\"price\":\"0.27\",\"size\":\"530\"},{\"price\":\"0.26\",\"size\":\"149.96\"},{\"price\":\"0.25\",\"size\":\"91.07\"},{\"price\":\"0.24\",\"size\":\"30\"},{\"price\":\"0.23\",\"size\":\"80.1\"},{\"price\":\"0.22\",\"size\":\"30\"}],\"tick_size\":\"0.01\",\"event_type\":\"book\",\"last_trade_price\":\"0.780\"},{\"market\":\"0x59cbdc98e569c31d3c33517131aa57a0a8d28e412df4a567d7df5b3ae9ec3de8\",\"asset_id\":\"85050326633307103921116183405959204984545408066775745936128241765963012426383\",\"timestamp\":\"1790267363323\",\"hash\":\"8d633fdb288fe25b3d3ab66c6ee600a8197761eb\",\"bids\":[{\"price\":\"0.01\",\"size\":\"1117\"},{\"price\":\"0.02\",\"size\":\"35.28\"},{\"price\":\"0.03\",\"size\":\"116.66\"},{\"price\":\"0.04\",\"size\":\"115.88\"},{\"price\":\"0.06\",\"size\":\"166.6\"},{\"price\":\"0.11\",\"size\":\"26.19\"},{\"price\":\"0.12\",\"size\":\"71.66\"}],\"asks\":[{\"price\":\"0.99\",\"size\":\"9.29\"},{\"price\":\"0.96\",\"size\":\"51\"},{\"price\":\"0.95\",\"size\":\"6.96\"},{\"price\":\"0.4\",\"size\":\"800\"},{\"price\":\"0.25\",\"size\":\"1000\"},{\"price\":\"0.21\",\"size\":\"50\"},{\"price\":\"0.19\",\"size\":\"5\"},{\"price\":\"0.18\",\"size\":\"116.54\"}],\"tick_size\":\"0.01\",\"event_type\":\"book\",\"last_trade_price\":\"0.870\"},{\"market\":\"0x16fcfe6c4bc8bf2fd210f1e3b5b0d55a2115a437923dc5730d63acb62c3366c9\",\"asset_id\":\"103355594346838123493217461284154957347949166061676890605566123828867704884418\",\"timestamp\":\"1790267338767\",\"hash\":\"06e2325e5300cb435a2acddd89c2a6704e00cd81\",\"bids\":[{\"price\":\"0.001\",\"size\":\"2005.85\"},{\"price\":\"0.002\",\"size\":\"2005\"},{\"price\":\"0.003\",\"size\":\"1112.63\"},{\"price\":\"0.004\",\"size\":\"800\"},{\"price\":\"0.005\",\"size\":\"48.98\"},{\"price\":\"0.007\",\"size\":\"50\"},{\"price\":\"0.01\",\"size\":\"20\"},{\"price\":\"0.011\",\"size\":\"7.82\"},{\"price\":\"0.022\",\"size\":\"53\"},{\"price\":\"0.023\",\"size\":\"55\"},{\"price\":\"0.027\",\"size\":\"102\"},{\"price\":\"0.03\",\"size\":\"82\"},{\"price\":\"0.033\",\"size\":\"56\"},{\"price\":\"0.044\",\"size\":\"155\"},{\"price\":\"0.052\",\"size\":\"195.28\"},{\"price\":\"0.053\",\"size\":\"100\"},{\"price\":\"0.054\",\"size\":\"5.18\"},{\"price\":\"0.055\",\"size\":\"36\"},{\"price\":\"0.15\",\"size\":\"10\"},{\"price\":\"0.2\",\"size\":\"10\"},{\"price\":\"0.25\",\"size\":\"10\"},{\"price\":\"0.3\",\"size\":\"10\"},{\"price\":\"0.331\",\"size\":\"393.99\"},{\"price\":\"0.332\",\"size\":\"243.28\"},{\"price\":\"0.333\",\"size\":\"8\"},{\"price\":\"0.334\",\"size\":\"92.05\"},{\"price\":\"0.337\",\"size\":\"11\"},{\"price\":\"0.338\",\"size\":\"48.29\"}],\"asks\":[{\"price\":\"0.999\",\"size\":\"1123110\"},{\"price\":\"0.998\",\"size\":\"50010.18\"},{\"price\":\"0.997\",\"size\":\"3000\"},{\"price\":\"0.996\",\"size\":\"90000\"},{\"price\":\"0.995\",\"size\":\"2000\"},{\"price\":\"0.994\",\"size\":\"6.18\"},{\"price\":\"0.99\",\"size\":\"20\"},{\"price\":\"0.988\",\"size\":\"9000\"},{\"price\":\"0.987\",\"size\":\"1000\"},{\"price\":\"0.977\",\"size\":\"500\"},{\"price\":\"0.976\",\"size\":\"14.35\"},{\"price\":\"0.84\",\"size\":\"1000\"},{\"price\":\"0.839\",\"size\":\"50\"},{\"price\":\"0.75\",\"size\":\"16.57\"},{\"price\":\"0.748\",\"size\":\"21.01\"},{\"price\":\"0.699\",\"size\":\"7.27\"},{\"price\":\"0.69\",\"size\":\"8.01\"},{\"price\":\"0.49\",\"size\":\"50\"},{\"price\":\"0.489\",\"size\":\"8.84\"}],\"tick_size\":\"0.001\",\"event_type\":\"book\",\"last_trade_price\":\"0.489\"}]\n"}
{"paper_only":true,"authenticated_execution":false,"real_order_submission":false,"real_capital_at_risk":false,"automatic_promotion":false,"execution_authority":false,"schema":"polymarket_v7_native_exact_arb_ws_frame_v1","model_sha":"f50147e18e02ebed76cabe900b708e4d9479e603","observer_session_id":"1790267378940-30808","session_manifest_sha256":"029412640e461b7cef08522eb6b6bce381d52d8001b3032f3af1960a7bd52ea0","feed_frame_sequence":2,"connection_epoch":1,"source_frame_valid":true,"decoded_events":2,"receive_wall_ms":1790267379221,"receive_monotonic_ns":1533843692178750,"decode_complete_monotonic_ns":1533843692246916,"graph_decision_start_ns":1533843692260416,"payload_sha256":"c28912e24f0ab75215be3547b7d76f23d4fe39c12931bb6ac48e45fbb947e7c4","payload":"{\"market\":\"0x12ed4858fd4aa92e1a644c74273ca76f49735c114d6833f8a3edef4f19e5ebff\", \"price_changes\":[{\"asset_id\":\"18054759644013870900749170809345467324611742242067616964612696305379357034954\", \"price\":\"0.6\", \"size\":\"0\", \"side\":\"BUY\", \"hash\":\"98c1441ebcd3cec3d17f7bf8efb9a8e282a40a0b\", \"best_bid\":\"0.61\", \"best_ask\":\"0.66\"}, {\"asset_id\":\"35599907049186982879557420969598528789434547136942253652554709047485665633870\", \"price\":\"0.4\", \"size\":\"0\", \"side\":\"SELL\", \"hash\":\"39c7b689ad8c782f1fcffba622350990cfb7c316\", \"best_bid\":\"0.34\", \"best_ask\":\"0.39\"}], \"timestamp\":\"1790267379229\", \"event_type\":\"price_change\"}"}
{"paper_only":true,"authenticated_execution":false,"real_order_submission":false,"real_capital_at_risk":false,"automatic_promotion":false,"execution_authority":false,"schema":"polymarket_v7_native_exact_arb_ws_frame_v1","model_sha":"f50147e18e02ebed76cabe900b708e4d9479e603","observer_session_id":"1790267378940-30808","session_manifest_sha256":"029412640e461b7cef08522eb6b6bce381d52d8001b3032f3af1960a7bd52ea0","feed_frame_sequence":5,"connection_epoch":1,"source_frame_valid":true,"decoded_events":2,"receive_wall_ms":1790267379245,"receive_monotonic_ns":1533843716331166,"decode_complete_monotonic_ns":1533843716438458,"graph_decision_start_ns":1533843716451375,"payload_sha256":"bb27505ae95b2eb77191e770897f86018b1961e8abe24052917a2602bc0f21d8","payload":"{\"market\":\"0x12ed4858fd4aa92e1a644c74273ca76f49735c114d6833f8a3edef4f19e5ebff\", \"price_changes\":[{\"asset_id\":\"18054759644013870900749170809345467324611742242067616964612696305379357034954\", \"price\":\"0.62\", \"size\":\"65.75\", \"side\":\"BUY\", \"hash\":\"1a7aa82ae9603a79667c9232ef191be39e0532b2\", \"best_bid\":\"0.62\", \"best_ask\":\"0.66\"}, {\"asset_id\":\"35599907049186982879557420969598528789434547136942253652554709047485665633870\", \"price\":\"0.38\", \"size\":\"65.75\", \"side\":\"SELL\", \"hash\":\"5a1dda499ceac37c00b9a859872d9d86dbcfcb39\", \"best_bid\":\"0.34\", \"best_ask\":\"0.38\"}], \"timestamp\":\"1790267379253\", \"event_type\":\"price_change\"}"}
{"paper_only":true,"authenticated_execution":false,"real_order_submission":false,"real_capital_at_risk":false,"automatic_promotion":false,"execution_authority":false,"schema":"polymarket_v7_native_exact_arb_ws_frame_v1","model_sha":"f50147e18e02ebed76cabe900b708e4d9479e603","observer_session_id":"1790267378940-30808","session_manifest_sha256":"029412640e461b7cef08522eb6b6bce381d52d8001b3032f3af1960a7bd52ea0","feed_frame_sequence":6,"connection_epoch":1,"source_frame_valid":true,"decoded_events":2,"receive_wall_ms":1790267381116,"receive_monotonic_ns":1533845587302583,"decode_complete_monotonic_ns":1533845587375958,"graph_decision_start_ns":1533845587390500,"payload_sha256":"5f5c00604b4218f2c21f2bf0db7745b5478e25acc90f2eea5a8f224bd4927aa4","payload":"{\"market\":\"0x9027a12cbbf78e9bff760402ab106732fa5a4af2002e4f48e5cc406ac1447800\", \"price_changes\":[{\"asset_id\":\"38175379283808228327034811002747441529537312086974479792536732908990840238523\", \"price\":\"0.13\", \"size\":\"183.78\", \"side\":\"BUY\", \"hash\":\"e0f0ecc3de1eb8cc38310ded937a074f8e254cd4\", \"best_bid\":\"0.2\", \"best_ask\":\"0.22\"}, {\"asset_id\":\"74866639935465906228822387344939614806982371503507376045493150406757418241698\", \"price\":\"0.87\", \"size\":\"183.78\", \"side\":\"SELL\", \"hash\":\"8f4fcb7fa04fd1051db5699134cbab4c8a05bfa9\", \"best_bid\":\"0.78\", \"best_ask\":\"0.8\"}], \"timestamp\":\"1790267381091\", \"event_type\":\"price_change\"}"}
{"paper_only":true,"authenticated_execution":false,"real_order_submission":false,"real_capital_at_risk":false,"automatic_promotion":false,"execution_authority":false,"schema":"polymarket_v7_native_exact_arb_ws_frame_v1","model_sha":"f50147e18e02ebed76cabe900b708e4d9479e603","observer_session_id":"1790267378940-30808","session_manifest_sha256":"029412640e461b7cef08522eb6b6bce381d52d8001b3032f3af1960a7bd52ea0","feed_frame_sequence":7,"connection_epoch":1,"source_frame_valid":true,"decoded_events":2,"receive_wall_ms":1790267381239,"receive_monotonic_ns":1533845710521125,"decode_complete_monotonic_ns":1533845710560333,"graph_decision_start_ns":1533845710566875,"payload_sha256":"2f26bb66cd1c8ac660fcd20b3295fc65a3076689e031900ed5940e026b8d4fb2","payload":"{\"market\":\"0x12ed4858fd4aa92e1a644c74273ca76f49735c114d6833f8a3edef4f19e5ebff\", \"price_changes\":[{\"asset_id\":\"18054759644013870900749170809345467324611742242067616964612696305379357034954\", \"price\":\"0.61\", \"size\":\"0\", \"side\":\"BUY\", \"hash\":\"c559b0622e378a014f21156a7636a26dd22f09bf\", \"best_bid\":\"0.62\", \"best_ask\":\"0.66\"}, {\"asset_id\":\"35599907049186982879557420969598528789434547136942253652554709047485665633870\", \"price\":\"0.39\", \"size\":\"0\", \"side\":\"SELL\", \"hash\":\"3949a35976d38b364e131eae0635fa41545af206\", \"best_bid\":\"0.34\", \"best_ask\":\"0.38\"}], \"timestamp\":\"1790267381247\", \"event_type\":\"price_change\"}"}
{"paper_only":true,"authenticated_execution":false,"real_order_submission":false,"real_capital_at_risk":false,"automatic_promotion":false,"execution_authority":false,"schema":"polymarket_v7_native_exact_arb_ws_frame_v1","model_sha":"f50147e18e02ebed76cabe900b708e4d9479e603","observer_session_id":"1790267378940-30808","session_manifest_sha256":"029412640e461b7cef08522eb6b6bce381d52d8001b3032f3af1960a7bd52ea0","feed_frame_sequence":10,"connection_epoch":1,"source_frame_valid":true,"decoded_events":2,"receive_wall_ms":1790267384626,"receive_monotonic_ns":1533849096993666,"decode_complete_monotonic_ns":1533849097041375,"graph_decision_start_ns":1533849097051500,"payload_sha256":"9f3b5a690f3cb8bf9d5b920768fb821d8dfbd94f466fc4f494d98311a487e2fe","payload":"{\"market\":\"0x12ed4858fd4aa92e1a644c74273ca76f49735c114d6833f8a3edef4f19e5ebff\", \"price_changes\":[{\"asset_id\":\"18054759644013870900749170809345467324611742242067616964612696305379357034954\", \"price\":\"0.62\", \"size\":\"0\", \"side\":\"BUY\", \"hash\":\"3fd1cc9a83063338575d71acb08f3014623870e7\", \"best_bid\":\"0.59\", \"best_ask\":\"0.66\"}, {\"asset_id\":\"35599907049186982879557420969598528789434547136942253652554709047485665633870\", \"price\":\"0.38\", \"size\":\"0\", \"side\":\"SELL\", \"hash\":\"692432badcf9732f2f82c3dde114f5c9344c997b\", \"best_bid\":\"0.34\", \"best_ask\":\"0.41\"}], \"timestamp\":\"1790267384632\", \"event_type\":\"price_change\"}"}
{"paper_only":true,"authenticated_execution":false,"real_order_submission":false,"real_capital_at_risk":false,"automatic_promotion":false,"execution_authority":false,"schema":"polymarket_v7_native_exact_arb_ws_frame_v1","model_sha":"f50147e18e02ebed76cabe900b708e4d9479e603","observer_session_id":"1790267378940-30808","session_manifest_sha256":"029412640e461b7cef08522eb6b6bce381d52d8001b3032f3af1960a7bd52ea0","feed_frame_sequence":13,"connection_epoch":1,"source_frame_valid":true,"decoded_events":2,"receive_wall_ms":1790267384683,"receive_monotonic_ns":1533849154430541,"decode_complete_monotonic_ns":1533849154493208,"graph_decision_start_ns":1533849154504333,"payload_sha256":"3486f0e94035273734ec2edfdf133fc13e093605f71d83f491cd76cf5ba4c56a","payload":"{\"market\":\"0x12ed4858fd4aa92e1a644c74273ca76f49735c114d6833f8a3edef4f19e5ebff\", \"price_changes\":[{\"asset_id\":\"18054759644013870900749170809345467324611742242067616964612696305379357034954\", \"price\":\"0.6\", \"size\":\"67.34\", \"side\":\"BUY\", \"hash\":\"75ab91549442c14acdc654834067ee95c64930e0\", \"best_bid\":\"0.6\", \"best_ask\":\"0.66\"}, {\"asset_id\":\"35599907049186982879557420969598528789434547136942253652554709047485665633870\", \"price\":\"0.4\", \"size\":\"67.34\", \"side\":\"SELL\", \"hash\":\"2caf157e2ff84698eb8731eaa8d6b8628dc23ce9\", \"best_bid\":\"0.34\", \"best_ask\":\"0.4\"}], \"timestamp\":\"1790267384683\", \"event_type\":\"price_change\"}"}
{"paper_only":true,"authenticated_execution":false,"real_order_submission":false,"real_capital_at_risk":false,"automatic_promotion":false,"execution_authority":false,"schema":"polymarket_v7_native_exact_arb_ws_frame_v1","model_sha":"f50147e18e02ebed76cabe900b708e4d9479e603","observer_session_id":"1790267378940-30808","session_manifest_sha256":"029412640e461b7cef08522eb6b6bce381d52d8001b3032f3af1960a7bd52ea0","feed_frame_sequence":16,"connection_epoch":1,"source_frame_valid":true,"decoded_events":2,"receive_wall_ms":1790267384960,"receive_monotonic_ns":1533849431251708,"decode_complete_monotonic_ns":1533849431309208,"graph_decision_start_ns":1533849431319958,"payload_sha256":"d3e5353d53c910cc3e622c69332341ab9e38de9ea12db904e1535f78e44fe327","payload":"{\"market\":\"0x12ed4858fd4aa92e1a644c74273ca76f49735c114d6833f8a3edef4f19e5ebff\", \"price_changes\":[{\"asset_id\":\"18054759644013870900749170809345467324611742242067616964612696305379357034954\", \"price\":\"0.61\", \"size\":\"30\", \"side\":\"BUY\", \"hash\":\"1878f976a6aca93924ed19b82fd92bbbbdb1ce64\", \"best_bid\":\"0.61\", \"best_ask\":\"0.66\"}, {\"asset_id\":\"35599907049186982879557420969598528789434547136942253652554709047485665633870\", \"price\":\"0.39\", \"size\":\"30\", \"side\":\"SELL\", \"hash\":\"9fdc45f9812daef41b131b8b53fb2ab47a4beadb\", \"best_bid\":\"0.34\", \"best_ask\":\"0.39\"}], \"timestamp\":\"1790267384967\", \"event_type\":\"price_change\"}"}
{"paper_only":true,"authenticated_execution":false,"real_order_submission":false,"real_capital_at_risk":false,"automatic_promotion":false,"execution_authority":false,"schema":"polymarket_v7_native_exact_arb_ws_frame_v1","model_sha":"f50147e18e02ebed76cabe900b708e4d9479e603","observer_session_id":"1790267378940-30808","session_manifest_sha256":"029412640e461b7cef08522eb6b6bce381d52d8001b3032f3af1960a7bd52ea0","feed_frame_sequence":19,"connection_epoch":1,"source_frame_valid":true,"decoded_events":2,"receive_wall_ms":1790267387469,"receive_monotonic_ns":1533851940197125,"decode_complete_monotonic_ns":1533851940260125,"graph_decision_start_ns":1533851940272875,"payload_sha256":"a4272808610570cd9f6f0eedf32e869c468eff3b3cc514225de835f5b67463d1","payload":"{\"market\":\"0x12ed4858fd4aa92e1a644c74273ca76f49735c114d6833f8a3edef4f19e5ebff\", \"price_changes\":[{\"asset_id\":\"18054759644013870900749170809345467324611742242067616964612696305379357034954\", \"price\":\"0.61\", \"size\":\"0\", \"side\":\"BUY\", \"hash\":\"59ce5d34aa15d42cb7323efd92b17d88d76b2b53\", \"best_bid\":\"0.6\", \"best_ask\":\"0.66\"}, {\"asset_id\":\"35599907049186982879557420969598528789434547136942253652554709047485665633870\", \"price\":\"0.39\", \"size\":\"0\", \"side\":\"SELL\", \"hash\":\"96ab5ff21fd1fa3aaad8ac34fa91b94904159707\", \"best_bid\":\"0.34\", \"best_ask\":\"0.4\"}], \"timestamp\":\"1790267387477\", \"event_type\":\"price_change\"}"}
{"paper_only":true,"authenticated_execution":false,"real_order_submission":false,"real_capital_at_risk":false,"automatic_promotion":false,"execution_authority":false,"schema":"polymarket_v7_native_exact_arb_ws_frame_v1","model_sha":"f50147e18e02ebed76cabe900b708e4d9479e603","observer_session_id":"1790267378940-30808","session_manifest_sha256":"029412640e461b7cef08522eb6b6bce381d52d8001b3032f3af1960a7bd52ea0","feed_frame_sequence":22,"connection_epoch":1,"source_frame_valid":true,"decoded_events":2,"receive_wall_ms":1790267390530,"receive_monotonic_ns":1533855001419625,"decode_complete_monotonic_ns":1533855001482000,"graph_decision_start_ns":1533855001493041,"payload_sha256":"f66b416268386a2a77de67e3500df7a8a76de3b325c9818fd7e7a2c935bd122a","payload":"{\"market\":\"0x12ed4858fd4aa92e1a644c74273ca76f49735c114d6833f8a3edef4f19e5ebff\", \"price_changes\":[{\"asset_id\":\"18054759644013870900749170809345467324611742242067616964612696305379357034954\", \"price\":\"0.61\", \"size\":\"30\", \"side\":\"BUY\", \"hash\":\"9b6f35520688804d2b223b51402f09e7d71e32d3\", \"best_bid\":\"0.61\", \"best_ask\":\"0.66\"}, {\"asset_id\":\"35599907049186982879557420969598528789434547136942253652554709047485665633870\", \"price\":\"0.39\", \"size\":\"30\", \"side\":\"SELL\", \"hash\":\"033dbbf2edba899cba40b5232d9d9557d0271ce3\", \"best_bid\":\"0.34\", \"best_ask\":\"0.39\"}], \"timestamp\":\"1790267390537\", \"event_type\":\"price_change\"}"}
{"paper_only":true,"authenticated_execution":false,"real_order_submission":false,"real_capital_at_risk":false,"automatic_promotion":false,"execution_authority":false,"schema":"polymarket_v7_native_exact_arb_ws_frame_v1","model_sha":"f50147e18e02ebed76cabe900b708e4d9479e603","observer_session_id":"1790267378940-30808","session_manifest_sha256":"029412640e461b7cef08522eb6b6bce381d52d8001b3032f3af1960a7bd52ea0","feed_frame_sequence":23,"connection_epoch":1,"source_frame_valid":true,"decoded_events":2,"receive_wall_ms":1790267391128,"receive_monotonic_ns":1533855599582708,"decode_complete_monotonic_ns":1533855599657458,"graph_decision_start_ns":1533855599669333,"payload_sha256":"cb06e939d5ec7cdd0f8e4d19745004d04a16ab26a5750b109d524c4ad12924a5","payload":"{\"market\":\"0xf31dc5f107bb556840fffa2bd0a503f891d82e61b0b7764e60cd92faec52a919\", \"price_changes\":[{\"asset_id\":\"16838256597398998291202588470738646116436652176742659727357735781336617089713\", \"price\":\"0.878\", \"size\":\"37\", \"side\":\"SELL\", \"hash\":\"19f6d87db4342e2f91a78f12476930be14d7cd39\", \"best_bid\":\"0.85\", \"best_ask\":\"0.878\"}, {\"asset_id\":\"82810327953012498612382200175108254608097289209592945267796930988226249448409\", \"price\":\"0.122\", \"size\":\"37\", \"side\":\"BUY\", \"hash\":\"f1a8d08e420f8bb75f47efbcc3af94c857aa5c12\", \"best_bid\":\"0.122\", \"best_ask\":\"0.15\"}], \"timestamp\":\"1790267391136\", \"event_type\":\"price_change\"}"}
{"paper_only":true,"authenticated_execution":false,"real_order_submission":false,"real_capital_at_risk":false,"automatic_promotion":false,"execution_authority":false,"schema":"polymarket_v7_native_exact_arb_ws_frame_v1","model_sha":"f50147e18e02ebed76cabe900b708e4d9479e603","observer_session_id":"1790267378940-30808","session_manifest_sha256":"029412640e461b7cef08522eb6b6bce381d52d8001b3032f3af1960a7bd52ea0","feed_frame_sequence":24,"connection_epoch":1,"source_frame_valid":true,"decoded_events":2,"receive_wall_ms":1790267392158,"receive_monotonic_ns":1533856629270875,"decode_complete_monotonic_ns":1533856629346750,"graph_decision_start_ns":1533856629359166,"payload_sha256":"db072f7d8cb02b67fa5648abb7580aa4084f032df9e21f7cbed8ac3234fd6c4f","payload":"{\"market\":\"0xd0e73ac0d00e8caf9cb7e74bcb024f94e57f34847f80ec2d4a0e3c57dbee7f19\", \"price_changes\":[{\"asset_id\":\"62313236991955111601391854345293627475130543547194366725001724474611291151185\", \"price\":\"0.01\", \"size\":\"116.09\", \"side\":\"BUY\", \"hash\":\"a27f072971bebbef076f3c144ce66696b9c7f857\", \"best_bid\":\"0.55\", \"best_ask\":\"0.78\"}, {\"asset_id\":\"18110789428391406482230306080653613096309178214543987995456679527322864131310\", \"price\":\"0.99\", \"size\":\"116.09\", \"side\":\"SELL\", \"hash\":\"9dafde4eb1a8c21447ec4e4deecced5c7d026e8e\", \"best_bid\":\"0.22\", \"best_ask\":\"0.45\"}], \"timestamp\":\"1790267392165\", \"event_type\":\"price_change\"}"}
{"paper_only":true,"authenticated_execution":false,"real_order_submission":false,"real_capital_at_risk":false,"automatic_promotion":false,"execution_authority":false,"schema":"polymarket_v7_native_exact_arb_ws_frame_v1","model_sha":"f50147e18e02ebed76cabe900b708e4d9479e603","observer_session_id":"1790267378940-30808","session_manifest_sha256":"029412640e461b7cef08522eb6b6bce381d52d8001b3032f3af1960a7bd52ea0","feed_frame_sequence":25,"connection_epoch":1,"source_frame_valid":true,"decoded_events":2,"receive_wall_ms":1790267392418,"receive_monotonic_ns":1533856889219416,"decode_complete_monotonic_ns":1533856889268791,"graph_decision_start_ns":1533856889274125,"payload_sha256":"9f0a091c723b2c7833cce52b52ac4c31980e1667efce6c6875d926826442d709","payload":"{\"market\":\"0xd0e73ac0d00e8caf9cb7e74bcb024f94e57f34847f80ec2d4a0e3c57dbee7f19\", \"price_changes\":[{\"asset_id\":\"62313236991955111601391854345293627475130543547194366725001724474611291151185\", \"price\":\"0.01\", \"size\":\"16.09\", \"side\":\"BUY\", \"hash\":\"5fda4feee6fa48aa3e91545b46063bb43d39c408\", \"best_bid\":\"0.55\", \"best_ask\":\"0.78\"}, {\"asset_id\":\"18110789428391406482230306080653613096309178214543987995456679527322864131310\", \"price\":\"0.99\", \"size\":\"16.09\", \"side\":\"SELL\", \"hash\":\"01c1b47b6308f37b9473ccf587e7aa60a5205b0f\", \"best_bid\":\"0.22\", \"best_ask\":\"0.45\"}], \"timestamp\":\"1790267392426\", \"event_type\":\"price_change\"}"}
{"paper_only":true,"authenticated_execution":false,"real_order_submission":false,"real_capital_at_risk":false,"automatic_promotion":false,"execution_authority":false,"schema":"polymarket_v7_native_exact_arb_ws_frame_v1","model_sha":"f50147e18e02ebed76cabe900b708e4d9479e603","observer_session_id":"1790267378940-30808","session_manifest_sha256":"029412640e461b7cef08522eb6b6bce381d52d8001b3032f3af1960a7bd52ea0","feed_frame_sequence":28,"connection_epoch":1,"source_frame_valid":true,"decoded_events":2,"receive_wall_ms":1790267392805,"receive_monotonic_ns":1533857275782750,"decode_complete_monotonic_ns":1533857275842333,"graph_decision_start_ns":1533857275853208,"payload_sha256":"720e27518129a209845a2278ce3a51156c67289567c6a3d9305978a476ff7a6b","payload":"{\"market\":\"0x12ed4858fd4aa92e1a644c74273ca76f49735c114d6833f8a3edef4f19e5ebff\", \"price_changes\":[{\"asset_id\":\"18054759644013870900749170809345467324611742242067616964612696305379357034954\", \"price\":\"0.61\", \"size\":\"0\", \"side\":\"BUY\", \"hash\":\"e5f52bfa5f3f3969e002acebf8e1eb0260a2aed2\", \"best_bid\":\"0.6\", \"best_ask\":\"0.66\"}, {\"asset_id\":\"35599907049186982879557420969598528789434547136942253652554709047485665633870\", \"price\":\"0.39\", \"size\":\"0\", \"side\":\"SELL\", \"hash\":\"7d3bc21bad37dc5900f3755d1e53afaf6fb1cf6a\", \"best_bid\":\"0.34\", \"best_ask\":\"0.4\"}], \"timestamp\":\"1790267392813\", \"event_type\":\"price_change\"}"}
{"paper_only":true,"authenticated_execution":false,"real_order_submission":false,"real_capital_at_risk":false,"automatic_promotion":false,"execution_authority":false,"schema":"polymarket_v7_native_exact_arb_ws_frame_v1","model_sha":"f50147e18e02ebed76cabe900b708e4d9479e603","observer_session_id":"1790267378940-30808","session_manifest_sha256":"029412640e461b7cef08522eb6b6bce381d52d8001b3032f3af1960a7bd52ea0","feed_frame_sequence":31,"connection_epoch":1,"source_frame_valid":true,"decoded_events":2,"receive_wall_ms":1790267394353,"receive_monotonic_ns":1533858824406541,"decode_complete_monotonic_ns":1533858824465875,"graph_decision_start_ns":1533858824480541,"payload_sha256":"1fdc61493438c8813287a47b18da9083da47307d16418c5b74341b4808b9a54d","payload":"{\"market\":\"0x12ed4858fd4aa92e1a644c74273ca76f49735c114d6833f8a3edef4f19e5ebff\", \"price_changes\":[{\"asset_id\":\"18054759644013870900749170809345467324611742242067616964612696305379357034954\", \"price\":\"0.61\", \"size\":\"30\", \"side\":\"BUY\", \"hash\":\"d0b4265ccaa44d66f7e2619ae4a65ac2d6222883\", \"best_bid\":\"0.61\", \"best_ask\":\"0.66\"}, {\"asset_id\":\"35599907049186982879557420969598528789434547136942253652554709047485665633870\", \"price\":\"0.39\", \"size\":\"30\", \"side\":\"SELL\", \"hash\":\"7e65323dbff7138c0f48c313869bafa9c4e974e5\", \"best_bid\":\"0.34\", \"best_ask\":\"0.39\"}], \"timestamp\":\"1790267394361\", \"event_type\":\"price_change\"}"}
{"paper_only":true,"authenticated_execution":false,"real_order_submission":false,"real_capital_at_risk":false,"automatic_promotion":false,"execution_authority":false,"schema":"polymarket_v7_native_exact_arb_ws_frame_v1","model_sha":"f50147e18e02ebed76cabe900b708e4d9479e603","observer_session_id":"1790267378940-30808","session_manifest_sha256":"029412640e461b7cef08522eb6b6bce381d52d8001b3032f3af1960a7bd52ea0","feed_frame_sequence":32,"connection_epoch":1,"source_frame_valid":true,"decoded_events":2,"receive_wall_ms":1790267395330,"receive_monotonic_ns":1533859801608750,"decode_complete_monotonic_ns":1533859801671000,"graph_decision_start_ns":1533859801680666,"payload_sha256":"db4498e5edb585cffe335e7312dbad62d53087d6596477f3e2ac0c8a10f84fa3","payload":"{\"market\":\"0x12ed4858fd4aa92e1a644c74273ca76f49735c114d6833f8a3edef4f19e5ebff\", \"price_changes\":[{\"asset_id\":\"18054759644013870900749170809345467324611742242067616964612696305379357034954\", \"price\":\"0.6\", \"size\":\"0\", \"side\":\"BUY\", \"hash\":\"402202dc121226bab8770d4e49c8d39c025614ac\", \"best_bid\":\"0.61\", \"best_ask\":\"0.66\"}, {\"asset_id\":\"35599907049186982879557420969598528789434547136942253652554709047485665633870\", \"price\":\"0.4\", \"size\":\"0\", \"side\":\"SELL\", \"hash\":\"a75c0d986ab46b89bdab23c4f17c04b5dd380a3c\", \"best_bid\":\"0.34\", \"best_ask\":\"0.39\"}], \"timestamp\":\"1790267395335\", \"event_type\":\"price_change\"}"}
{"paper_only":true,"authenticated_execution":false,"real_order_submission":false,"real_capital_at_risk":false,"automatic_promotion":false,"execution_authority":false,"schema":"polymarket_v7_native_exact_arb_ws_frame_v1","model_sha":"f50147e18e02ebed76cabe900b708e4d9479e603","observer_session_id":"1790267378940-30808","session_manifest_sha256":"029412640e461b7cef08522eb6b6bce381d52d8001b3032f3af1960a7bd52ea0","feed_frame_sequence":35,"connection_epoch":1,"source_frame_valid":true,"decoded_events":2,"receive_wall_ms":1790267395341,"receive_monotonic_ns":1533859812706375,"decode_complete_monotonic_ns":1533859812729541,"graph_decision_start_ns":1533859812734291,"payload_sha256":"72855baea3d86b4a03d88823a146227f174516c3d743f96c774e368986569034","payload":"{\"market\":\"0x12ed4858fd4aa92e1a644c74273ca76f49735c114d6833f8a3edef4f19e5ebff\", \"price_changes\":[{\"asset_id\":\"18054759644013870900749170809345467324611742242067616964612696305379357034954\", \"price\":\"0.62\", \"size\":\"65.75\", \"side\":\"BUY\", \"hash\":\"196f0d6dcfb2410330f6e2db9f53eafaf964b386\", \"best_bid\":\"0.62\", \"best_ask\":\"0.66\"}, {\"asset_id\":\"35599907049186982879557420969598528789434547136942253652554709047485665633870\", \"price\":\"0.38\", \"size\":\"65.75\", \"side\":\"SELL\", \"hash\":\"f589808485350ce8d3aae1b03b590a5435ae987a\", \"best_bid\":\"0.34\", \"best_ask\":\"0.38\"}], \"timestamp\":\"1790267395348\", \"event_type\":\"price_change\"}"}
{"paper_only":true,"authenticated_execution":false,"real_order_submission":false,"real_capital_at_risk":false,"automatic_promotion":false,"execution_authority":false,"schema":"polymarket_v7_native_exact_arb_ws_frame_v1","model_sha":"f50147e18e02ebed76cabe900b708e4d9479e603","observer_session_id":"1790267378940-30808","session_manifest_sha256":"029412640e461b7cef08522eb6b6bce381d52d8001b3032f3af1960a7bd52ea0","feed_frame_sequence":36,"connection_epoch":1,"source_frame_valid":true,"decoded_events":2,"receive_wall_ms":1790267396749,"receive_monotonic_ns":1533861220026000,"decode_complete_monotonic_ns":1533861220095875,"graph_decision_start_ns":1533861220111625,"payload_sha256":"c62fc349cf1ca9a0557f1ec17912d814d12aac5b5a8ccfee8e109f7501f07098","payload":"{\"market\":\"0x12ed4858fd4aa92e1a644c74273ca76f49735c114d6833f8a3edef4f19e5ebff\", \"price_changes\":[{\"asset_id\":\"18054759644013870900749170809345467324611742242067616964612696305379357034954\", \"price\":\"0.61\", \"size\":\"0\", \"side\":\"BUY\", \"hash\":\"2f2636683da81c0d06eea30fad9a0a2ce165fd52\", \"best_bid\":\"0.62\", \"best_ask\":\"0.66\"}, {\"asset_id\":\"35599907049186982879557420969598528789434547136942253652554709047485665633870\", \"price\":\"0.39\", \"size\":\"0\", \"side\":\"SELL\", \"hash\":\"7b06dc4eb17fb23fefc5419dca06df72fa306f27\", \"best_bid\":\"0.34\", \"best_ask\":\"0.38\"}], \"timestamp\":\"1790267396754\", \"event_type\":\"price_change\"}"}
{"paper_only":true,"authenticated_execution":false,"real_order_submission":false,"real_capital_at_risk":false,"automatic_promotion":false,"execution_authority":false,"schema":"polymarket_v7_native_exact_arb_ws_frame_v1","model_sha":"f50147e18e02ebed76cabe900b708e4d9479e603","observer_session_id":"1790267378940-30808","session_manifest_sha256":"029412640e461b7cef08522eb6b6bce381d52d8001b3032f3af1960a7bd52ea0","feed_frame_sequence":39,"connection_epoch":1,"source_frame_valid":true,"decoded_events":2,"receive_wall_ms":1790267400403,"receive_monotonic_ns":1533864873745666,"decode_complete_monotonic_ns":1533864873768458,"graph_decision_start_ns":1533864873775416,"payload_sha256":"e51ecc3a40616fccb20b09b9e182247c5ac898f6a2e3b4c5db7ac09735730f43","payload":"{\"market\":\"0x12ed4858fd4aa92e1a644c74273ca76f49735c114d6833f8a3edef4f19e5ebff\", \"price_changes\":[{\"asset_id\":\"18054759644013870900749170809345467324611742242067616964612696305379357034954\", \"price\":\"0.62\", \"size\":\"0\", \"side\":\"BUY\", \"hash\":\"fe5adf46245633b9dd4ca9f6fe046d503149de4c\", \"best_bid\":\"0.59\", \"best_ask\":\"0.66\"}, {\"asset_id\":\"35599907049186982879557420969598528789434547136942253652554709047485665633870\", \"price\":\"0.38\", \"size\":\"0\", \"side\":\"SELL\", \"hash\":\"761a1a9827941e5ba8175b45a2c46b856e0bf2e0\", \"best_bid\":\"0.34\", \"best_ask\":\"0.41\"}], \"timestamp\":\"1790267400409\", \"event_type\":\"price_change\"}"}
{"paper_only":true,"authenticated_execution":false,"real_order_submission":false,"real_capital_at_risk":false,"automatic_promotion":false,"execution_authority":false,"schema":"polymarket_v7_native_exact_arb_ws_frame_v1","model_sha":"f50147e18e02ebed76cabe900b708e4d9479e603","observer_session_id":"1790267378940-30808","session_manifest_sha256":"029412640e461b7cef08522eb6b6bce381d52d8001b3032f3af1960a7bd52ea0","feed_frame_sequence":42,"connection_epoch":1,"source_frame_valid":true,"decoded_events":2,"receive_wall_ms":1790267400447,"receive_monotonic_ns":1533864918210458,"decode_complete_monotonic_ns":1533864918232833,"graph_decision_start_ns":1533864918238333,"payload_sha256":"aa8349d1b0d1a9d9237120db72c03f522103d68d5ea8a4f61923875aeb984b4f","payload":"{\"market\":\"0x12ed4858fd4aa92e1a644c74273ca76f49735c114d6833f8a3edef4f19e5ebff\", \"price_changes\":[{\"asset_id\":\"18054759644013870900749170809345467324611742242067616964612696305379357034954\", \"price\":\"0.6\", \"size\":\"67.34\", \"side\":\"BUY\", \"hash\":\"060f0b7717ab54a233c110f724c130092bcd89fa\", \"best_bid\":\"0.6\", \"best_ask\":\"0.66\"}, {\"asset_id\":\"35599907049186982879557420969598528789434547136942253652554709047485665633870\", \"price\":\"0.4\", \"size\":\"67.34\", \"side\":\"SELL\", \"hash\":\"d2e43b653423228f23fe501ed06636678192ecc7\", \"best_bid\":\"0.34\", \"best_ask\":\"0.4\"}], \"timestamp\":\"1790267400452\", \"event_type\":\"price_change\"}"}
{"paper_only":true,"authenticated_execution":false,"real_order_submission":false,"real_capital_at_risk":false,"automatic_promotion":false,"execution_authority":false,"schema":"polymarket_v7_native_exact_arb_ws_frame_v1","model_sha":"f50147e18e02ebed76cabe900b708e4d9479e603","observer_session_id":"1790267378940-30808","session_manifest_sha256":"029412640e461b7cef08522eb6b6bce381d52d8001b3032f3af1960a7bd52ea0","feed_frame_sequence":45,"connection_epoch":1,"source_frame_valid":true,"decoded_events":2,"receive_wall_ms":1790267401238,"receive_monotonic_ns":1533865709197166,"decode_complete_monotonic_ns":1533865709253708,"graph_decision_start_ns":1533865709265250,"payload_sha256":"fae65f66547cfaaa9358b261351789fafa789d20df70fb8d48cf10b6e5a49191","payload":"{\"market\":\"0x12ed4858fd4aa92e1a644c74273ca76f49735c114d6833f8a3edef4f19e5ebff\", \"price_changes\":[{\"asset_id\":\"18054759644013870900749170809345467324611742242067616964612696305379357034954\", \"price\":\"0.61\", \"size\":\"30\", \"side\":\"BUY\", \"hash\":\"994fffe454901e4540e21563421c77a28c84c842\", \"best_bid\":\"0.61\", \"best_ask\":\"0.66\"}, {\"asset_id\":\"35599907049186982879557420969598528789434547136942253652554709047485665633870\", \"price\":\"0.39\", \"size\":\"30\", \"side\":\"SELL\", \"hash\":\"28fcbbd8af9e0276c20cbecac254bffa225d4dae\", \"best_bid\":\"0.34\", \"best_ask\":\"0.39\"}], \"timestamp\":\"1790267401232\", \"event_type\":\"price_change\"}"}
{"paper_only":true,"authenticated_execution":false,"real_order_submission":false,"real_capital_at_risk":false,"automatic_promotion":false,"execution_authority":false,"schema":"polymarket_v7_native_exact_arb_ws_frame_v1","model_sha":"f50147e18e02ebed76cabe900b708e4d9479e603","observer_session_id":"1790267378940-30808","session_manifest_sha256":"029412640e461b7cef08522eb6b6bce381d52d8001b3032f3af1960a7bd52ea0","feed_frame_sequence":46,"connection_epoch":1,"source_frame_valid":true,"decoded_events":2,"receive_wall_ms":1790267403018,"receive_monotonic_ns":1533867489290833,"decode_complete_monotonic_ns":1533867489364500,"graph_decision_start_ns":1533867489380375,"payload_sha256":"f8f4658157733af47557f34a7ec3494d443225090bd0c74a01ed08923c945cc7","payload":"{\"market\":\"0xf31dc5f107bb556840fffa2bd0a503f891d82e61b0b7764e60cd92faec52a919\", \"price_changes\":[{\"asset_id\":\"16838256597398998291202588470738646116436652176742659727357735781336617089713\", \"price\":\"0.841\", \"size\":\"100\", \"side\":\"BUY\", \"hash\":\"3b2bf0ad58aa213aae6e92b98b579aed17e9d65e\", \"best_bid\":\"0.85\", \"best_ask\":\"0.878\"}, {\"asset_id\":\"82810327953012498612382200175108254608097289209592945267796930988226249448409\", \"price\":\"0.159\", \"size\":\"100\", \"side\":\"SELL\", \"hash\":\"33dbad6c02cd00734ce07772baf3fa1fea48e03e\", \"best_bid\":\"0.122\", \"best_ask\":\"0.15\"}], \"timestamp\":\"1790267403021\", \"event_type\":\"price_change\"}"}
{"paper_only":true,"authenticated_execution":false,"real_order_submission":false,"real_capital_at_risk":false,"automatic_promotion":false,"execution_authority":false,"schema":"polymarket_v7_native_exact_arb_ws_frame_v1","model_sha":"f50147e18e02ebed76cabe900b708e4d9479e603","observer_session_id":"1790267378940-30808","session_manifest_sha256":"029412640e461b7cef08522eb6b6bce381d52d8001b3032f3af1960a7bd52ea0","feed_frame_sequence":47,"connection_epoch":1,"source_frame_valid":true,"decoded_events":2,"receive_wall_ms":1790267403018,"receive_monotonic_ns":1533867489464333,"decode_complete_monotonic_ns":1533867489509041,"graph_decision_start_ns":1533867489515333,"payload_sha256":"4754f807fab7062ab9632fdedf5d96eb76506c183f22df387d2c59c163d0cf64","payload":"{\"market\":\"0xf31dc5f107bb556840fffa2bd0a503f891d82e61b0b7764e60cd92faec52a919\", \"price_changes\":[{\"asset_id\":\"82810327953012498612382200175108254608097289209592945267796930988226249448409\", \"price\":\"0.113\", \"size\":\"100\", \"side\":\"BUY\", \"hash\":\"4fc8756176015c6b7cb87853d303c6a099f69b3f\", \"best_bid\":\"0.122\", \"best_ask\":\"0.15\"}, {\"asset_id\":\"16838256597398998291202588470738646116436652176742659727357735781336617089713\", \"price\":\"0.887\", \"size\":\"100\", \"side\":\"SELL\", \"hash\":\"c5b6137d33780c073f96feb09578969b82bdfd12\", \"best_bid\":\"0.85\", \"best_ask\":\"0.878\"}], \"timestamp\":\"1790267403022\", \"event_type\":\"price_change\"}"}
{"paper_only":true,"authenticated_execution":false,"real_order_submission":false,"real_capital_at_risk":false,"automatic_promotion":false,"execution_authority":false,"schema":"polymarket_v7_native_exact_arb_ws_frame_v1","model_sha":"f50147e18e02ebed76cabe900b708e4d9479e603","observer_session_id":"1790267378940-30808","session_manifest_sha256":"029412640e461b7cef08522eb6b6bce381d52d8001b3032f3af1960a7bd52ea0","feed_frame_sequence":50,"connection_epoch":1,"source_frame_valid":true,"decoded_events":2,"receive_wall_ms":1790267404457,"receive_monotonic_ns":1533868927831000,"decode_complete_monotonic_ns":1533868927893291,"graph_decision_start_ns":1533868927904458,"payload_sha256":"613c34e9003a5e045930ab1189ddbbf0b3de5f8c04f63bc8317e14188098ab84","payload":"{\"market\":\"0x12ed4858fd4aa92e1a644c74273ca76f49735c114d6833f8a3edef4f19e5ebff\", \"price_changes\":[{\"asset_id\":\"18054759644013870900749170809345467324611742242067616964612696305379357034954\", \"price\":\"0.61\", \"size\":\"0\", \"side\":\"BUY\", \"hash\":\"57222e4ccb6c3e9076df3158890cf43f38cb7512\", \"best_bid\":\"0.6\", \"best_ask\":\"0.66\"}, {\"asset_id\":\"35599907049186982879557420969598528789434547136942253652554709047485665633870\", \"price\":\"0.39\", \"size\":\"0\", \"side\":\"SELL\", \"hash\":\"5a192b5bd5d4f3c3e2f8bea02819c70718d3d30e\", \"best_bid\":\"0.34\", \"best_ask\":\"0.4\"}], \"timestamp\":\"1790267404460\", \"event_type\":\"price_change\"}"}
{"paper_only":true,"authenticated_execution":false,"real_order_submission":false,"real_capital_at_risk":false,"automatic_promotion":false,"execution_authority":false,"schema":"polymarket_v7_native_exact_arb_ws_frame_v1","model_sha":"f50147e18e02ebed76cabe900b708e4d9479e603","observer_session_id":"1790267378940-30808","session_manifest_sha256":"029412640e461b7cef08522eb6b6bce381d52d8001b3032f3af1960a7bd52ea0","feed_frame_sequence":53,"connection_epoch":1,"source_frame_valid":true,"decoded_events":2,"receive_wall_ms":1790267407491,"receive_monotonic_ns":1533871961998500,"decode_complete_monotonic_ns":1533871962027583,"graph_decision_start_ns":1533871962034125,"payload_sha256":"12d03b209eee9219d2c209c6a5c6fccdbd59a4a7db4bd7b4e09ec7609e574dd0","payload":"{\"market\":\"0x12ed4858fd4aa92e1a644c74273ca76f49735c114d6833f8a3edef4f19e5ebff\", \"price_changes\":[{\"asset_id\":\"18054759644013870900749170809345467324611742242067616964612696305379357034954\", \"price\":\"0.61\", \"size\":\"30\", \"side\":\"BUY\", \"hash\":\"3bfc26e609435b537ed5641cbe7387df34955673\", \"best_bid\":\"0.61\", \"best_ask\":\"0.66\"}, {\"asset_id\":\"35599907049186982879557420969598528789434547136942253652554709047485665633870\", \"price\":\"0.39\", \"size\":\"30\", \"side\":\"SELL\", \"hash\":\"d1277a6c245c7dab8681f637b90455833c1147dc\", \"best_bid\":\"0.34\", \"best_ask\":\"0.39\"}], \"timestamp\":\"1790267407492\", \"event_type\":\"price_change\"}"}
{"paper_only":true,"authenticated_execution":false,"real_order_submission":false,"real_capital_at_risk":false,"automatic_promotion":false,"execution_authority":false,"schema":"polymarket_v7_native_exact_arb_ws_frame_v1","model_sha":"f50147e18e02ebed76cabe900b708e4d9479e603","observer_session_id":"1790267378940-30808","session_manifest_sha256":"029412640e461b7cef08522eb6b6bce381d52d8001b3032f3af1960a7bd52ea0","feed_frame_sequence":56,"connection_epoch":1,"source_frame_valid":true,"decoded_events":2,"receive_wall_ms":1790267409767,"receive_monotonic_ns":1533874238439708,"decode_complete_monotonic_ns":1533874238502000,"graph_decision_start_ns":1533874238516708,"payload_sha256":"c07a7e42ee05cad5b6e37874abb51acf46629998000fac97e9e762618b8fc69c","payload":"{\"market\":\"0x12ed4858fd4aa92e1a644c74273ca76f49735c114d6833f8a3edef4f19e5ebff\", \"price_changes\":[{\"asset_id\":\"18054759644013870900749170809345467324611742242067616964612696305379357034954\", \"price\":\"0.61\", \"size\":\"0\", \"side\":\"BUY\", \"hash\":\"7a895439483a29aba0f9e8cb2df2c1131cb65c7b\", \"best_bid\":\"0.6\", \"best_ask\":\"0.66\"}, {\"asset_id\":\"35599907049186982879557420969598528789434547136942253652554709047485665633870\", \"price\":\"0.39\", \"size\":\"0\", \"side\":\"SELL\", \"hash\":\"94e6469f7583ca3aeaa04b0fdcd678623eca6590\", \"best_bid\":\"0.34\", \"best_ask\":\"0.4\"}], \"timestamp\":\"1790267409759\", \"event_type\":\"price_change\"}"}
{"paper_only":true,"authenticated_execution":false,"real_order_submission":false,"real_capital_at_risk":false,"automatic_promotion":false,"execution_authority":false,"schema":"polymarket_v7_native_exact_arb_ws_frame_v1","model_sha":"f50147e18e02ebed76cabe900b708e4d9479e603","observer_session_id":"1790267378940-30808","session_manifest_sha256":"029412640e461b7cef08522eb6b6bce381d52d8001b3032f3af1960a7bd52ea0","feed_frame_sequence":57,"connection_epoch":1,"source_frame_valid":true,"decoded_events":2,"receive_wall_ms":1790267412389,"receive_monotonic_ns":1533876860369458,"decode_complete_monotonic_ns":1533876860440291,"graph_decision_start_ns":1533876860454083,"payload_sha256":"cec29fe27acdb036b5ae9870a74a4e41b3ef3159e47079fec067c97b9d042aba","payload":"{\"market\":\"0x9027a12cbbf78e9bff760402ab106732fa5a4af2002e4f48e5cc406ac1447800\", \"price_changes\":[{\"asset_id\":\"38175379283808228327034811002747441529537312086974479792536732908990840238523\", \"price\":\"0.12\", \"size\":\"79.93\", \"side\":\"BUY\", \"hash\":\"da7c95d056f012a6b4ffed01eb33e07fd5466be3\", \"best_bid\":\"0.2\", \"best_ask\":\"0.22\"}, {\"asset_id\":\"74866639935465906228822387344939614806982371503507376045493150406757418241698\", \"price\":\"0.88\", \"size\":\"79.93\", \"side\":\"SELL\", \"hash\":\"80935fb578a8a2e18b4aa27b07d2e94779fdc2f8\", \"best_bid\":\"0.78\", \"best_ask\":\"0.8\"}], \"timestamp\":\"1790267412396\", \"event_type\":\"price_change\"}"}
{"paper_only":true,"authenticated_execution":false,"real_order_submission":false,"real_capital_at_risk":false,"automatic_promotion":false,"execution_authority":false,"schema":"polymarket_v7_native_exact_arb_ws_frame_v1","model_sha":"f50147e18e02ebed76cabe900b708e4d9479e603","observer_session_id":"1790267378940-30808","session_manifest_sha256":"029412640e461b7cef08522eb6b6bce381d52d8001b3032f3af1960a7bd52ea0","feed_frame_sequence":60,"connection_epoch":1,"source_frame_valid":true,"decoded_events":2,"receive_wall_ms":1790267412679,"receive_monotonic_ns":1533877149842083,"decode_complete_monotonic_ns":1533877149900625,"graph_decision_start_ns":1533877149912208,"payload_sha256":"350996c279ebbfdc2841acc63fdbcd5e48baaba57a6b9aabc8048f81e6a5857f","payload":"{\"market\":\"0x12ed4858fd4aa92e1a644c74273ca76f49735c114d6833f8a3edef4f19e5ebff\", \"price_changes\":[{\"asset_id\":\"18054759644013870900749170809345467324611742242067616964612696305379357034954\", \"price\":\"0.61\", \"size\":\"30\", \"side\":\"BUY\", \"hash\":\"5aa328df33f521779324e4953946303d13c638cf\", \"best_bid\":\"0.61\", \"best_ask\":\"0.66\"}, {\"asset_id\":\"35599907049186982879557420969598528789434547136942253652554709047485665633870\", \"price\":\"0.39\", \"size\":\"30\", \"side\":\"SELL\", \"hash\":\"6227ec691f391d6e28379a4e02e8216e7cc8eedb\", \"best_bid\":\"0.34\", \"best_ask\":\"0.39\"}], \"timestamp\":\"1790267412687\", \"event_type\":\"price_change\"}"}
{"paper_only":true,"authenticated_execution":false,"real_order_submission":false,"real_capital_at_risk":false,"automatic_promotion":false,"execution_authority":false,"schema":"polymarket_v7_native_exact_arb_ws_frame_v1","model_sha":"f50147e18e02ebed76cabe900b708e4d9479e603","observer_session_id":"1790267378940-30808","session_manifest_sha256":"029412640e461b7cef08522eb6b6bce381d52d8001b3032f3af1960a7bd52ea0","feed_frame_sequence":63,"connection_epoch":1,"source_frame_valid":true,"decoded_events":2,"receive_wall_ms":1790267415047,"receive_monotonic_ns":1533879518013000,"decode_complete_monotonic_ns":1533879518072375,"graph_decision_start_ns":1533879518086083,"payload_sha256":"eb839d6f032e9c440e3b6cb584c6c0f71c204f4bd8d53893675ddc7f4e907f2a","payload":"{\"market\":\"0x12ed4858fd4aa92e1a644c74273ca76f49735c114d6833f8a3edef4f19e5ebff\", \"price_changes\":[{\"asset_id\":\"18054759644013870900749170809345467324611742242067616964612696305379357034954\", \"price\":\"0.61\", \"size\":\"0\", \"side\":\"BUY\", \"hash\":\"b88a3d34c04c6aaf5ba4c60bbb349c662e6bda09\", \"best_bid\":\"0.6\", \"best_ask\":\"0.66\"}, {\"asset_id\":\"35599907049186982879557420969598528789434547136942253652554709047485665633870\", \"price\":\"0.39\", \"size\":\"0\", \"side\":\"SELL\", \"hash\":\"4fcf58ec92c1a567a041f9739d6b2647c73e2301\", \"best_bid\":\"0.34\", \"best_ask\":\"0.4\"}], \"timestamp\":\"1790267415050\", \"event_type\":\"price_change\"}"}
{"paper_only":true,"authenticated_execution":false,"real_order_submission":false,"real_capital_at_risk":false,"automatic_promotion":false,"execution_authority":false,"schema":"polymarket_v7_native_exact_arb_ws_frame_v1","model_sha":"f50147e18e02ebed76cabe900b708e4d9479e603","observer_session_id":"1790267378940-30808","session_manifest_sha256":"029412640e461b7cef08522eb6b6bce381d52d8001b3032f3af1960a7bd52ea0","feed_frame_sequence":66,"connection_epoch":1,"source_frame_valid":true,"decoded_events":2,"receive_wall_ms":1790267417308,"receive_monotonic_ns":1533881779665250,"decode_complete_monotonic_ns":1533881779729125,"graph_decision_start_ns":1533881779741125,"payload_sha256":"c879c1e3998ba2a31ec71c9a67fd935b65d1fd75ec766f34dbdfd854f0ef64cf","payload":"{\"market\":\"0x12ed4858fd4aa92e1a644c74273ca76f49735c114d6833f8a3edef4f19e5ebff\", \"price_changes\":[{\"asset_id\":\"18054759644013870900749170809345467324611742242067616964612696305379357034954\", \"price\":\"0.61\", \"size\":\"30\", \"side\":\"BUY\", \"hash\":\"7057591d77f864e8faa4eb7aefbcc06e3262617e\", \"best_bid\":\"0.61\", \"best_ask\":\"0.66\"}, {\"asset_id\":\"35599907049186982879557420969598528789434547136942253652554709047485665633870\", \"price\":\"0.39\", \"size\":\"30\", \"side\":\"SELL\", \"hash\":\"d90149ed6c9fa616ecc0fb3703945eb3ecce59dc\", \"best_bid\":\"0.34\", \"best_ask\":\"0.39\"}], \"timestamp\":\"1790267417308\", \"event_type\":\"price_change\"}"}
{"paper_only":true,"authenticated_execution":false,"real_order_submission":false,"real_capital_at_risk":false,"automatic_promotion":false,"execution_authority":false,"schema":"polymarket_v7_native_exact_arb_ws_frame_v1","model_sha":"f50147e18e02ebed76cabe900b708e4d9479e603","observer_session_id":"1790267378940-30808","session_manifest_sha256":"029412640e461b7cef08522eb6b6bce381d52d8001b3032f3af1960a7bd52ea0","feed_frame_sequence":69,"connection_epoch":1,"source_frame_valid":true,"decoded_events":2,"receive_wall_ms":1790267417953,"receive_monotonic_ns":1533882424170916,"decode_complete_monotonic_ns":1533882424233125,"graph_decision_start_ns":1533882424244750,"payload_sha256":"343aa65e399c25e1269237662ce0dc29ba9b23cfc0c38a397fa55045e1fff6c8","payload":"{\"market\":\"0x12ed4858fd4aa92e1a644c74273ca76f49735c114d6833f8a3edef4f19e5ebff\", \"price_changes\":[{\"asset_id\":\"18054759644013870900749170809345467324611742242067616964612696305379357034954\", \"price\":\"0.62\", \"size\":\"65.75\", \"side\":\"BUY\", \"hash\":\"070819e83de2dc688c97d0a31cc96a0f83a391dd\", \"best_bid\":\"0.62\", \"best_ask\":\"0.66\"}, {\"asset_id\":\"35599907049186982879557420969598528789434547136942253652554709047485665633870\", \"price\":\"0.38\", \"size\":\"65.75\", \"side\":\"SELL\", \"hash\":\"6e4fd0b46c60dbd63482002224e1087091ba107b\", \"best_bid\":\"0.34\", \"best_ask\":\"0.38\"}], \"timestamp\":\"1790267417960\", \"event_type\":\"price_change\"}"}
{"paper_only":true,"authenticated_execution":false,"real_order_submission":false,"real_capital_at_risk":false,"automatic_promotion":false,"execution_authority":false,"schema":"polymarket_v7_native_exact_arb_ws_frame_v1","model_sha":"f50147e18e02ebed76cabe900b708e4d9479e603","observer_session_id":"1790267378940-30808","session_manifest_sha256":"029412640e461b7cef08522eb6b6bce381d52d8001b3032f3af1960a7bd52ea0","feed_frame_sequence":70,"connection_epoch":1,"source_frame_valid":true,"decoded_events":2,"receive_wall_ms":1790267417957,"receive_monotonic_ns":1533882428206125,"decode_complete_monotonic_ns":1533882428250000,"graph_decision_start_ns":1533882428256541,"payload_sha256":"b151279bdf06aeef167fb53742a51e4316f9834cae1e33427cff72da8d025999","payload":"{\"market\":\"0x12ed4858fd4aa92e1a644c74273ca76f49735c114d6833f8a3edef4f19e5ebff\", \"price_changes\":[{\"asset_id\":\"18054759644013870900749170809345467324611742242067616964612696305379357034954\", \"price\":\"0.6\", \"size\":\"0\", \"side\":\"BUY\", \"hash\":\"4b63512d31c131d7043571ab16f899ede2dbbffe\", \"best_bid\":\"0.62\", \"best_ask\":\"0.66\"}, {\"asset_id\":\"35599907049186982879557420969598528789434547136942253652554709047485665633870\", \"price\":\"0.4\", \"size\":\"0\", \"side\":\"SELL\", \"hash\":\"74ecf8220a0163416fd9a3b709eab640fe4b9752\", \"best_bid\":\"0.34\", \"best_ask\":\"0.38\"}], \"timestamp\":\"1790267417964\", \"event_type\":\"price_change\"}"}
{"paper_only":true,"authenticated_execution":false,"real_order_submission":false,"real_capital_at_risk":false,"automatic_promotion":false,"execution_authority":false,"schema":"polymarket_v7_native_exact_arb_ws_frame_v1","model_sha":"f50147e18e02ebed76cabe900b708e4d9479e603","observer_session_id":"1790267378940-30808","session_manifest_sha256":"029412640e461b7cef08522eb6b6bce381d52d8001b3032f3af1960a7bd52ea0","feed_frame_sequence":71,"connection_epoch":1,"source_frame_valid":true,"decoded_events":2,"receive_wall_ms":1790267419534,"receive_monotonic_ns":1533884005511125,"decode_complete_monotonic_ns":1533884005585583,"graph_decision_start_ns":1533884005597958,"payload_sha256":"15a96512e449f8784f299d41dd4950d273cc9e08c11db36ffe1a0ee454ad9e12","payload":"{\"market\":\"0x12ed4858fd4aa92e1a644c74273ca76f49735c114d6833f8a3edef4f19e5ebff\", \"price_changes\":[{\"asset_id\":\"18054759644013870900749170809345467324611742242067616964612696305379357034954\", \"price\":\"0.61\", \"size\":\"0\", \"side\":\"BUY\", \"hash\":\"bcc55359fc6143c59334cf8841a9ee95aeac0920\", \"best_bid\":\"0.62\", \"best_ask\":\"0.66\"}, {\"asset_id\":\"35599907049186982879557420969598528789434547136942253652554709047485665633870\", \"price\":\"0.39\", \"size\":\"0\", \"side\":\"SELL\", \"hash\":\"ad9609fd11e5b2218ef4edf3e385311f518e290f\", \"best_bid\":\"0.34\", \"best_ask\":\"0.38\"}], \"timestamp\":\"1790267419538\", \"event_type\":\"price_change\"}"}
{"paper_only":true,"authenticated_execution":false,"real_order_submission":false,"real_capital_at_risk":false,"automatic_promotion":false,"execution_authority":false,"schema":"polymarket_v7_native_exact_arb_ws_frame_v1","model_sha":"f50147e18e02ebed76cabe900b708e4d9479e603","observer_session_id":"1790267378940-30808","session_manifest_sha256":"029412640e461b7cef08522eb6b6bce381d52d8001b3032f3af1960a7bd52ea0","feed_frame_sequence":72,"connection_epoch":1,"source_frame_valid":true,"decoded_events":2,"receive_wall_ms":1790267423251,"receive_monotonic_ns":1533887722137625,"decode_complete_monotonic_ns":1533887722208333,"graph_decision_start_ns":1533887722224916,"payload_sha256":"6640e5910d5637ed1804f8c57e4886b913315c46ac1109b7fcda5429e2919fee","payload":"{\"market\":\"0xf31dc5f107bb556840fffa2bd0a503f891d82e61b0b7764e60cd92faec52a919\", \"price_changes\":[{\"asset_id\":\"16838256597398998291202588470738646116436652176742659727357735781336617089713\", \"price\":\"0.843\", \"size\":\"323\", \"side\":\"BUY\", \"hash\":\"ed1a2cce52ddb63f10b1b8c39ecb6b38c4f08eef\", \"best_bid\":\"0.85\", \"best_ask\":\"0.878\"}, {\"asset_id\":\"82810327953012498612382200175108254608097289209592945267796930988226249448409\", \"price\":\"0.157\", \"size\":\"323\", \"side\":\"SELL\", \"hash\":\"51106bd703da28568c0a6b932290cc23a4c9c391\", \"best_bid\":\"0.122\", \"best_ask\":\"0.15\"}], \"timestamp\":\"1790267423243\", \"event_type\":\"price_change\"}"}
{"paper_only":true,"authenticated_execution":false,"real_order_submission":false,"real_capital_at_risk":false,"automatic_promotion":false,"execution_authority":false,"schema":"polymarket_v7_native_exact_arb_ws_frame_v1","model_sha":"f50147e18e02ebed76cabe900b708e4d9479e603","observer_session_id":"1790267378940-30808","session_manifest_sha256":"029412640e461b7cef08522eb6b6bce381d52d8001b3032f3af1960a7bd52ea0","feed_frame_sequence":73,"connection_epoch":1,"source_frame_valid":true,"decoded_events":2,"receive_wall_ms":1790267423580,"receive_monotonic_ns":1533888051496625,"decode_complete_monotonic_ns":1533888051589250,"graph_decision_start_ns":1533888051608958,"payload_sha256":"1a1dec039f1e24cc224013fcfbcc620a903f92e0cb5a11ddde5f7ee70199b826","payload":"{\"market\":\"0xc48e17e33742004e4ec5d3386d05f7d723f1c2da37b5cbc56e9ce432e13d8ed4\", \"price_changes\":[{\"asset_id\":\"61335977902549040838647614340959106920439456466051953454810638023705765740133\", \"price\":\"0.01\", \"size\":\"0\", \"side\":\"BUY\", \"hash\":\"f0d4f69b866e20293bac90313b92010e871dcfa9\", \"best_bid\":\"0.41\", \"best_ask\":\"0.43\"}, {\"asset_id\":\"50067946737985819644638241783771238619616055560007143911749636220745966692358\", \"price\":\"0.99\", \"size\":\"0\", \"side\":\"SELL\", \"hash\":\"5219c7dd75812c05567517456e7f2c36e4c341e5\", \"best_bid\":\"0.57\", \"best_ask\":\"0.59\"}], \"timestamp\":\"1790267423587\", \"event_type\":\"price_change\"}"}
{"paper_only":true,"authenticated_execution":false,"real_order_submission":false,"real_capital_at_risk":false,"automatic_promotion":false,"execution_authority":false,"schema":"polymarket_v7_native_exact_arb_ws_frame_v1","model_sha":"f50147e18e02ebed76cabe900b708e4d9479e603","observer_session_id":"1790267378940-30808","session_manifest_sha256":"029412640e461b7cef08522eb6b6bce381d52d8001b3032f3af1960a7bd52ea0","feed_frame_sequence":76,"connection_epoch":1,"source_frame_valid":true,"decoded_events":2,"receive_wall_ms":1790267423924,"receive_monotonic_ns":1533888394975666,"decode_complete_monotonic_ns":1533888395038750,"graph_decision_start_ns":1533888395050333,"payload_sha256":"9f45bb30eeba345ad280e481e5711bf2330bfcbffd39fd780cb7319f28d1f52c","payload":"{\"market\":\"0x12ed4858fd4aa92e1a644c74273ca76f49735c114d6833f8a3edef4f19e5ebff\", \"price_changes\":[{\"asset_id\":\"18054759644013870900749170809345467324611742242067616964612696305379357034954\", \"price\":\"0.62\", \"size\":\"0\", \"side\":\"BUY\", \"hash\":\"f176548c71eec2498da38ba52fb521339a735dfa\", \"best_bid\":\"0.59\", \"best_ask\":\"0.66\"}, {\"asset_id\":\"35599907049186982879557420969598528789434547136942253652554709047485665633870\", \"price\":\"0.38\", \"size\":\"0\", \"side\":\"SELL\", \"hash\":\"0e106380eb2da1209e728c4f3e59db4f0578962c\", \"best_bid\":\"0.34\", \"best_ask\":\"0.41\"}], \"timestamp\":\"1790267423928\", \"event_type\":\"price_change\"}"}
{"paper_only":true,"authenticated_execution":false,"real_order_submission":false,"real_capital_at_risk":false,"automatic_promotion":false,"execution_authority":false,"schema":"polymarket_v7_native_exact_arb_ws_frame_v1","model_sha":"f50147e18e02ebed76cabe900b708e4d9479e603","observer_session_id":"1790267378940-30808","session_manifest_sha256":"029412640e461b7cef08522eb6b6bce381d52d8001b3032f3af1960a7bd52ea0","feed_frame_sequence":79,"connection_epoch":1,"source_frame_valid":true,"decoded_events":2,"receive_wall_ms":1790267424011,"receive_monotonic_ns":1533888482640375,"decode_complete_monotonic_ns":1533888482699708,"graph_decision_start_ns":1533888482709791,"payload_sha256":"30543b815e2a4f7a894dbe918dd2a9983fc89180f552ea087a89c4da16f6d7f3","payload":"{\"market\":\"0x12ed4858fd4aa92e1a644c74273ca76f49735c114d6833f8a3edef4f19e5ebff\", \"price_changes\":[{\"asset_id\":\"18054759644013870900749170809345467324611742242067616964612696305379357034954\", \"price\":\"0.6\", \"size\":\"67.34\", \"side\":\"BUY\", \"hash\":\"6603ff00c02b0ba522bcae4e41dbf6a8630ce0ce\", \"best_bid\":\"0.6\", \"best_ask\":\"0.66\"}, {\"asset_id\":\"35599907049186982879557420969598528789434547136942253652554709047485665633870\", \"price\":\"0.4\", \"size\":\"67.34\", \"side\":\"SELL\", \"hash\":\"0cc8c8ff6c24a18826bfc959b5d7103b4c3c82d9\", \"best_bid\":\"0.34\", \"best_ask\":\"0.4\"}], \"timestamp\":\"1790267424006\", \"event_type\":\"price_change\"}"}
{"paper_only":true,"authenticated_execution":false,"real_order_submission":false,"real_capital_at_risk":false,"automatic_promotion":false,"execution_authority":false,"schema":"polymarket_v7_native_exact_arb_ws_frame_v1","model_sha":"f50147e18e02ebed76cabe900b708e4d9479e603","observer_session_id":"1790267378940-30808","session_manifest_sha256":"029412640e461b7cef08522eb6b6bce381d52d8001b3032f3af1960a7bd52ea0","feed_frame_sequence":82,"connection_epoch":1,"source_frame_valid":true,"decoded_events":2,"receive_wall_ms":1790267424484,"receive_monotonic_ns":1533888955429791,"decode_complete_monotonic_ns":1533888955487208,"graph_decision_start_ns":1533888955499750,"payload_sha256":"af62807370842946b7da806cefe62946a84c492b8e70d6c60a93812f09a55970","payload":"{\"market\":\"0x12ed4858fd4aa92e1a644c74273ca76f49735c114d6833f8a3edef4f19e5ebff\", \"price_changes\":[{\"asset_id\":\"18054759644013870900749170809345467324611742242067616964612696305379357034954\", \"price\":\"0.61\", \"size\":\"30\", \"side\":\"BUY\", \"hash\":\"6d1ae52928dbf241701320b96ace999708509e88\", \"best_bid\":\"0.61\", \"best_ask\":\"0.66\"}, {\"asset_id\":\"35599907049186982879557420969598528789434547136942253652554709047485665633870\", \"price\":\"0.39\", \"size\":\"30\", \"side\":\"SELL\", \"hash\":\"fa143cfa59e48b035392039d9ef838f4069fd4a1\", \"best_bid\":\"0.34\", \"best_ask\":\"0.39\"}], \"timestamp\":\"1790267424489\", \"event_type\":\"price_change\"}"}
{"paper_only":true,"authenticated_execution":false,"real_order_submission":false,"real_capital_at_risk":false,"automatic_promotion":false,"execution_authority":false,"schema":"polymarket_v7_native_exact_arb_ws_frame_v1","model_sha":"f50147e18e02ebed76cabe900b708e4d9479e603","observer_session_id":"1790267378940-30808","session_manifest_sha256":"029412640e461b7cef08522eb6b6bce381d52d8001b3032f3af1960a7bd52ea0","feed_frame_sequence":85,"connection_epoch":1,"source_frame_valid":true,"decoded_events":2,"receive_wall_ms":1790267426687,"receive_monotonic_ns":1533891158657083,"decode_complete_monotonic_ns":1533891158718416,"graph_decision_start_ns":1533891158733083,"payload_sha256":"69197ffd646f182d972e70c521ac14f8bf68fea6f97b071ab2aad3eda911d09a","payload":"{\"market\":\"0x12ed4858fd4aa92e1a644c74273ca76f49735c114d6833f8a3edef4f19e5ebff\", \"price_changes\":[{\"asset_id\":\"18054759644013870900749170809345467324611742242067616964612696305379357034954\", \"price\":\"0.61\", \"size\":\"0\", \"side\":\"BUY\", \"hash\":\"5ade7a5f41810159b724bf619fd67b0f6a2c55c4\", \"best_bid\":\"0.6\", \"best_ask\":\"0.66\"}, {\"asset_id\":\"35599907049186982879557420969598528789434547136942253652554709047485665633870\", \"price\":\"0.39\", \"size\":\"0\", \"side\":\"SELL\", \"hash\":\"4ae7a7cd7ac057543e343ecb4242d24bd1fde001\", \"best_bid\":\"0.34\", \"best_ask\":\"0.4\"}], \"timestamp\":\"1790267426687\", \"event_type\":\"price_change\"}"}
{"paper_only":true,"authenticated_execution":false,"real_order_submission":false,"real_capital_at_risk":false,"automatic_promotion":false,"execution_authority":false,"schema":"polymarket_v7_native_exact_arb_ws_frame_v1","model_sha":"f50147e18e02ebed76cabe900b708e4d9479e603","observer_session_id":"1790267378940-30808","session_manifest_sha256":"029412640e461b7cef08522eb6b6bce381d52d8001b3032f3af1960a7bd52ea0","feed_frame_sequence":88,"connection_epoch":1,"source_frame_valid":true,"decoded_events":2,"receive_wall_ms":1790267428872,"receive_monotonic_ns":1533893343600208,"decode_complete_monotonic_ns":1533893343660083,"graph_decision_start_ns":1533893343672666,"payload_sha256":"fde455fb14c358ee9f22f09dc18bb523191acb807d6cd55ffb2c8b40180a5788","payload":"{\"market\":\"0x12ed4858fd4aa92e1a644c74273ca76f49735c114d6833f8a3edef4f19e5ebff\", \"price_changes\":[{\"asset_id\":\"18054759644013870900749170809345467324611742242067616964612696305379357034954\", \"price\":\"0.61\", \"size\":\"30\", \"side\":\"BUY\", \"hash\":\"a3726e6f8de06a88241b74bd0205f2ad742e2fcd\", \"best_bid\":\"0.61\", \"best_ask\":\"0.66\"}, {\"asset_id\":\"35599907049186982879557420969598528789434547136942253652554709047485665633870\", \"price\":\"0.39\", \"size\":\"30\", \"side\":\"SELL\", \"hash\":\"22fe120392d294f201fbbee9a24300c245e99b80\", \"best_bid\":\"0.34\", \"best_ask\":\"0.39\"}], \"timestamp\":\"1790267428872\", \"event_type\":\"price_change\"}"}
{"paper_only":true,"authenticated_execution":false,"real_order_submission":false,"real_capital_at_risk":false,"automatic_promotion":false,"execution_authority":false,"schema":"polymarket_v7_native_exact_arb_ws_frame_v1","model_sha":"f50147e18e02ebed76cabe900b708e4d9479e603","observer_session_id":"1790267378940-30808","session_manifest_sha256":"029412640e461b7cef08522eb6b6bce381d52d8001b3032f3af1960a7bd52ea0","feed_frame_sequence":89,"connection_epoch":1,"source_frame_valid":true,"decoded_events":2,"receive_wall_ms":1790267430770,"receive_monotonic_ns":1533895241058583,"decode_complete_monotonic_ns":1533895241130666,"graph_decision_start_ns":1533895241142458,"payload_sha256":"cc06cc4bdbe2b729c47ba02d48d3b7e8e31cbfbf9a42ea8ada73d222d8e40642","payload":"{\"market\":\"0x12ed4858fd4aa92e1a644c74273ca76f49735c114d6833f8a3edef4f19e5ebff\", \"price_changes\":[{\"asset_id\":\"18054759644013870900749170809345467324611742242067616964612696305379357034954\", \"price\":\"0.6\", \"size\":\"0\", \"side\":\"BUY\", \"hash\":\"4e70a3649059677b56471b9c38a61ffb9bcca770\", \"best_bid\":\"0.61\", \"best_ask\":\"0.66\"}, {\"asset_id\":\"35599907049186982879557420969598528789434547136942253652554709047485665633870\", \"price\":\"0.4\", \"size\":\"0\", \"side\":\"SELL\", \"hash\":\"37118ef4285916864412f65c3fd234ee87a6a372\", \"best_bid\":\"0.34\", \"best_ask\":\"0.39\"}], \"timestamp\":\"1790267430771\", \"event_type\":\"price_change\"}"}
{"paper_only":true,"authenticated_execution":false,"real_order_submission":false,"real_capital_at_risk":false,"automatic_promotion":false,"execution_authority":false,"schema":"polymarket_v7_native_exact_arb_ws_frame_v1","model_sha":"f50147e18e02ebed76cabe900b708e4d9479e603","observer_session_id":"1790267378940-30808","session_manifest_sha256":"029412640e461b7cef08522eb6b6bce381d52d8001b3032f3af1960a7bd52ea0","feed_frame_sequence":92,"connection_epoch":1,"source_frame_valid":true,"decoded_events":2,"receive_wall_ms":1790267430801,"receive_monotonic_ns":1533895272385166,"decode_complete_monotonic_ns":1533895272439291,"graph_decision_start_ns":1533895272449083,"payload_sha256":"601757b85ebe1b45af5275010aee0072cd7d2c21e952acee6849422ad1d3a81d","payload":"{\"market\":\"0x12ed4858fd4aa92e1a644c74273ca76f49735c114d6833f8a3edef4f19e5ebff\", \"price_changes\":[{\"asset_id\":\"18054759644013870900749170809345467324611742242067616964612696305379357034954\", \"price\":\"0.62\", \"size\":\"65.75\", \"side\":\"BUY\", \"hash\":\"1b1307e002749646baec91a74acfa36a14660208\", \"best_bid\":\"0.62\", \"best_ask\":\"0.66\"}, {\"asset_id\":\"35599907049186982879557420969598528789434547136942253652554709047485665633870\", \"price\":\"0.38\", \"size\":\"65.75\", \"side\":\"SELL\", \"hash\":\"f3d7298ada15e7cdb588016f184d08f9713da878\", \"best_bid\":\"0.34\", \"best_ask\":\"0.38\"}], \"timestamp\":\"1790267430803\", \"event_type\":\"price_change\"}"}
{"paper_only":true,"authenticated_execution":false,"real_order_submission":false,"real_capital_at_risk":false,"automatic_promotion":false,"execution_authority":false,"schema":"polymarket_v7_native_exact_arb_ws_frame_v1","model_sha":"f50147e18e02ebed76cabe900b708e4d9479e603","observer_session_id":"1790267378940-30808","session_manifest_sha256":"029412640e461b7cef08522eb6b6bce381d52d8001b3032f3af1960a7bd52ea0","feed_frame_sequence":93,"connection_epoch":1,"source_frame_valid":true,"decoded_events":2,"receive_wall_ms":1790267432552,"receive_monotonic_ns":1533897023306750,"decode_complete_monotonic_ns":1533897023377750,"graph_decision_start_ns":1533897023389875,"payload_sha256":"40e2324c5fe4116cc886bfdb0c36ce7da00846e78ac72d0df8552002267a1a79","payload":"{\"market\":\"0x12ed4858fd4aa92e1a644c74273ca76f49735c114d6833f8a3edef4f19e5ebff\", \"price_changes\":[{\"asset_id\":\"18054759644013870900749170809345467324611742242067616964612696305379357034954\", \"price\":\"0.61\", \"size\":\"0\", \"side\":\"BUY\", \"hash\":\"c04ee0a629e9c95085ced4362741ade92a55e53b\", \"best_bid\":\"0.62\", \"best_ask\":\"0.66\"}, {\"asset_id\":\"35599907049186982879557420969598528789434547136942253652554709047485665633870\", \"price\":\"0.39\", \"size\":\"0\", \"side\":\"SELL\", \"hash\":\"cb85ddf4ebe202b36c74da94482c60491a1d2fc8\", \"best_bid\":\"0.34\", \"best_ask\":\"0.38\"}], \"timestamp\":\"1790267432558\", \"event_type\":\"price_change\"}"}
{"paper_only":true,"authenticated_execution":false,"real_order_submission":false,"real_capital_at_risk":false,"automatic_promotion":false,"execution_authority":false,"schema":"polymarket_v7_native_exact_arb_ws_frame_v1","model_sha":"f50147e18e02ebed76cabe900b708e4d9479e603","observer_session_id":"1790267378940-30808","session_manifest_sha256":"029412640e461b7cef08522eb6b6bce381d52d8001b3032f3af1960a7bd52ea0","feed_frame_sequence":96,"connection_epoch":1,"source_frame_valid":true,"decoded_events":2,"receive_wall_ms":1790267436558,"receive_monotonic_ns":1533901029174833,"decode_complete_monotonic_ns":1533901029280208,"graph_decision_start_ns":1533901029295750,"payload_sha256":"9065585735643f782f980eb2552dc2979845ac67ab0edd83e400fc258e602fa1","payload":"{\"market\":\"0x12ed4858fd4aa92e1a644c74273ca76f49735c114d6833f8a3edef4f19e5ebff\", \"price_changes\":[{\"asset_id\":\"18054759644013870900749170809345467324611742242067616964612696305379357034954\", \"price\":\"0.62\", \"size\":\"0\", \"side\":\"BUY\", \"hash\":\"794d55b82647d681b649ae4a6c12ecc8a0e71b87\", \"best_bid\":\"0.59\", \"best_ask\":\"0.66\"}, {\"asset_id\":\"35599907049186982879557420969598528789434547136942253652554709047485665633870\", \"price\":\"0.38\", \"size\":\"0\", \"side\":\"SELL\", \"hash\":\"14022dbd7eff793469bf228064c41db178fc03c1\", \"best_bid\":\"0.34\", \"best_ask\":\"0.41\"}], \"timestamp\":\"1790267436564\", \"event_type\":\"price_change\"}"}
{"paper_only":true,"authenticated_execution":false,"real_order_submission":false,"real_capital_at_risk":false,"automatic_promotion":false,"execution_authority":false,"schema":"polymarket_v7_native_exact_arb_ws_frame_v1","model_sha":"f50147e18e02ebed76cabe900b708e4d9479e603","observer_session_id":"1790267378940-30808","session_manifest_sha256":"029412640e461b7cef08522eb6b6bce381d52d8001b3032f3af1960a7bd52ea0","feed_frame_sequence":99,"connection_epoch":1,"source_frame_valid":true,"decoded_events":2,"receive_wall_ms":1790267436934,"receive_monotonic_ns":1533901405758583,"decode_complete_monotonic_ns":1533901405819000,"graph_decision_start_ns":1533901405831083,"payload_sha256":"aa7caace06ec1102417e1d312d8a4d526705d49fe1e2f1c1e60d09283a5c3f06","payload":"{\"market\":\"0x12ed4858fd4aa92e1a644c74273ca76f49735c114d6833f8a3edef4f19e5ebff\", \"price_changes\":[{\"asset_id\":\"18054759644013870900749170809345467324611742242067616964612696305379357034954\", \"price\":\"0.6\", \"size\":\"67.34\", \"side\":\"BUY\", \"hash\":\"c2d414f4f2cc0a41eee99ed68867664cbe3f88a3\", \"best_bid\":\"0.6\", \"best_ask\":\"0.66\"}, {\"asset_id\":\"35599907049186982879557420969598528789434547136942253652554709047485665633870\", \"price\":\"0.4\", \"size\":\"67.34\", \"side\":\"SELL\", \"hash\":\"cccbe15c83ea4dd5ccbb635faf359f57d1bca292\", \"best_bid\":\"0.34\", \"best_ask\":\"0.4\"}], \"timestamp\":\"1790267436942\", \"event_type\":\"price_change\"}"}
{"paper_only":true,"authenticated_execution":false,"real_order_submission":false,"real_capital_at_risk":false,"automatic_promotion":false,"execution_authority":false,"schema":"polymarket_v7_native_exact_arb_ws_frame_v1","model_sha":"f50147e18e02ebed76cabe900b708e4d9479e603","observer_session_id":"1790267378940-30808","session_manifest_sha256":"029412640e461b7cef08522eb6b6bce381d52d8001b3032f3af1960a7bd52ea0","feed_frame_sequence":102,"connection_epoch":1,"source_frame_valid":true,"decoded_events":2,"receive_wall_ms":1790267437574,"receive_monotonic_ns":1533902045065583,"decode_complete_monotonic_ns":1533902045089791,"graph_decision_start_ns":1533902045094583,"payload_sha256":"cd6c6e507ddf225468f532f0d8047ad956444c9b8858945a70576465e41d74c7","payload":"{\"market\":\"0x12ed4858fd4aa92e1a644c74273ca76f49735c114d6833f8a3edef4f19e5ebff\", \"price_changes\":[{\"asset_id\":\"18054759644013870900749170809345467324611742242067616964612696305379357034954\", \"price\":\"0.61\", \"size\":\"30\", \"side\":\"BUY\", \"hash\":\"9c97f999dc028fdc88ef259bcfc0058c0009d0c2\", \"best_bid\":\"0.61\", \"best_ask\":\"0.66\"}, {\"asset_id\":\"35599907049186982879557420969598528789434547136942253652554709047485665633870\", \"price\":\"0.39\", \"size\":\"30\", \"side\":\"SELL\", \"hash\":\"00dfec28d4869f9b46544e1606cca18cd27fb834\", \"best_bid\":\"0.34\", \"best_ask\":\"0.39\"}], \"timestamp\":\"1790267437575\", \"event_type\":\"price_change\"}"}
{"paper_only":true,"authenticated_execution":false,"real_order_submission":false,"real_capital_at_risk":false,"automatic_promotion":false,"execution_authority":false,"schema":"polymarket_v7_native_exact_arb_ws_frame_v1","model_sha":"f50147e18e02ebed76cabe900b708e4d9479e603","observer_session_id":"1790267378940-30808","session_manifest_sha256":"029412640e461b7cef08522eb6b6bce381d52d8001b3032f3af1960a7bd52ea0","feed_frame_sequence":103,"connection_epoch":1,"source_frame_valid":true,"decoded_events":2,"receive_wall_ms":1790267439247,"receive_monotonic_ns":1533903718515541,"decode_complete_monotonic_ns":1533903718633166,"graph_decision_start_ns":1533903718726041,"payload_sha256":"2fc6918d8e18a53555a217687fffafbb1ff97d4647f7b32bf7f4635a840ed077","payload":"{\"market\":\"0xf31dc5f107bb556840fffa2bd0a503f891d82e61b0b7764e60cd92faec52a919\", \"price_changes\":[{\"asset_id\":\"16838256597398998291202588470738646116436652176742659727357735781336617089713\", \"price\":\"0.006\", \"size\":\"54.67\", \"side\":\"BUY\", \"hash\":\"d61e4d700354e25382ffdb9c7fe1a3406d1d69c3\", \"best_bid\":\"0.85\", \"best_ask\":\"0.878\"}, {\"asset_id\":\"82810327953012498612382200175108254608097289209592945267796930988226249448409\", \"price\":\"0.994\", \"size\":\"54.67\", \"side\":\"SELL\", \"hash\":\"7ed3ce708d6855cec67c9ccd089951c20a5cf14c\", \"best_bid\":\"0.122\", \"best_ask\":\"0.15\"}], \"timestamp\":\"1790267439246\", \"event_type\":\"price_change\"}"}
{"paper_only":true,"authenticated_execution":false,"real_order_submission":false,"real_capital_at_risk":false,"automatic_promotion":false,"execution_authority":false,"schema":"polymarket_v7_native_exact_arb_ws_frame_v1","model_sha":"f50147e18e02ebed76cabe900b708e4d9479e603","observer_session_id":"1790267378940-30808","session_manifest_sha256":"029412640e461b7cef08522eb6b6bce381d52d8001b3032f3af1960a7bd52ea0","feed_frame_sequence":104,"connection_epoch":1,"source_frame_valid":true,"decoded_events":2,"receive_wall_ms":1790267439247,"receive_monotonic_ns":1533903718862666,"decode_complete_monotonic_ns":1533903718933666,"graph_decision_start_ns":1533903718944500,"payload_sha256":"8c31be801d7c3c617f1b56a78a0d9411b0310441552cb75191ce074033b869fc","payload":"{\"market\":\"0xf31dc5f107bb556840fffa2bd0a503f891d82e61b0b7764e60cd92faec52a919\", \"price_changes\":[{\"asset_id\":\"16838256597398998291202588470738646116436652176742659727357735781336617089713\", \"price\":\"0.003\", \"size\":\"11486.93\", \"side\":\"BUY\", \"hash\":\"49bc469838acf9e9eb772c67762c1b80bc705fc8\", \"best_bid\":\"0.85\", \"best_ask\":\"0.878\"}, {\"asset_id\":\"82810327953012498612382200175108254608097289209592945267796930988226249448409\", \"price\":\"0.997\", \"size\":\"11486.93\", \"side\":\"SELL\", \"hash\":\"c16ee406071ee1174d683e910c08d30774fe34f9\", \"best_bid\":\"0.122\", \"best_ask\":\"0.15\"}], \"timestamp\":\"1790267439247\", \"event_type\":\"price_change\"}"}
{"paper_only":true,"authenticated_execution":false,"real_order_submission":false,"real_capital_at_risk":false,"automatic_promotion":false,"execution_authority":false,"schema":"polymarket_v7_native_exact_arb_ws_frame_v1","model_sha":"f50147e18e02ebed76cabe900b708e4d9479e603","observer_session_id":"1790267378940-30808","session_manifest_sha256":"029412640e461b7cef08522eb6b6bce381d52d8001b3032f3af1960a7bd52ea0","feed_frame_sequence":105,"connection_epoch":1,"source_frame_valid":true,"decoded_events":2,"receive_wall_ms":1790267439248,"receive_monotonic_ns":1533903719121000,"decode_complete_monotonic_ns":1533903719205166,"graph_decision_start_ns":1533903719215416,"payload_sha256":"a91d94b24fae5df23c9e0e657a26386ff1be747a638add1e312ae22fadf6b5d5","payload":"{\"market\":\"0xf31dc5f107bb556840fffa2bd0a503f891d82e61b0b7764e60cd92faec52a919\", \"price_changes\":[{\"asset_id\":\"16838256597398998291202588470738646116436652176742659727357735781336617089713\", \"price\":\"0.001\", \"size\":\"5473.05\", \"side\":\"BUY\", \"hash\":\"dbe8bb8b22899ff5172ae028ff6257570ae73363\", \"best_bid\":\"0.85\", \"best_ask\":\"0.878\"}, {\"asset_id\":\"82810327953012498612382200175108254608097289209592945267796930988226249448409\", \"price\":\"0.999\", \"size\":\"5473.05\", \"side\":\"SELL\", \"hash\":\"d28c70f69433940c7af5d8cafb7a1e8234734123\", \"best_bid\":\"0.122\", \"best_ask\":\"0.15\"}], \"timestamp\":\"1790267439248\", \"event_type\":\"price_change\"}"}
{"paper_only":true,"authenticated_execution":false,"real_order_submission":false,"real_capital_at_risk":false,"automatic_promotion":false,"execution_authority":false,"schema":"polymarket_v7_native_exact_arb_ws_frame_v1","model_sha":"f50147e18e02ebed76cabe900b708e4d9479e603","observer_session_id":"1790267378940-30808","session_manifest_sha256":"029412640e461b7cef08522eb6b6bce381d52d8001b3032f3af1960a7bd52ea0","feed_frame_sequence":106,"connection_epoch":1,"source_frame_valid":true,"decoded_events":2,"receive_wall_ms":1790267439248,"receive_monotonic_ns":1533903719295083,"decode_complete_monotonic_ns":1533903719357583,"graph_decision_start_ns":1533903719365958,"payload_sha256":"b67b42bfa21fc8bdb314ab5dea22ccb7a94c9811984978b6ae306c527817a38e","payload":"{\"market\":\"0xf31dc5f107bb556840fffa2bd0a503f891d82e61b0b7764e60cd92faec52a919\", \"price_changes\":[{\"asset_id\":\"16838256597398998291202588470738646116436652176742659727357735781336617089713\", \"price\":\"0.014\", \"size\":\"38.07\", \"side\":\"BUY\", \"hash\":\"a51652da0fc6c698c8a5778c67dd0a7b51342b90\", \"best_bid\":\"0.85\", \"best_ask\":\"0.878\"}, {\"asset_id\":\"82810327953012498612382200175108254608097289209592945267796930988226249448409\", \"price\":\"0.986\", \"size\":\"38.07\", \"side\":\"SELL\", \"hash\":\"5508067c45fc4e50c250c99e5c334b697aea1d67\", \"best_bid\":\"0.122\", \"best_ask\":\"0.15\"}], \"timestamp\":\"1790267439249\", \"event_type\":\"price_change\"}"}
{"paper_only":true,"authenticated_execution":false,"real_order_submission":false,"real_capital_at_risk":false,"automatic_promotion":false,"execution_authority":false,"schema":"polymarket_v7_native_exact_arb_ws_frame_v1","model_sha":"f50147e18e02ebed76cabe900b708e4d9479e603","observer_session_id":"1790267378940-30808","session_manifest_sha256":"029412640e461b7cef08522eb6b6bce381d52d8001b3032f3af1960a7bd52ea0","feed_frame_sequence":107,"connection_epoch":1,"source_frame_valid":true,"decoded_events":2,"receive_wall_ms":1790267439278,"receive_monotonic_ns":1533903749076166,"decode_complete_monotonic_ns":1533903749146208,"graph_decision_start_ns":1533903749159375,"payload_sha256":"6c2ec7e2cc1efed689d4640c1b9dd068aca810a76bd5974d7449173ccbe66fbb","payload":"{\"market\":\"0xf31dc5f107bb556840fffa2bd0a503f891d82e61b0b7764e60cd92faec52a919\", \"price_changes\":[{\"asset_id\":\"16838256597398998291202588470738646116436652176742659727357735781336617089713\", \"price\":\"0.844\", \"size\":\"626.42\", \"side\":\"BUY\", \"hash\":\"a4df72dd9729657893e1be4e44d49e8d6b8706a3\", \"best_bid\":\"0.85\", \"best_ask\":\"0.878\"}, {\"asset_id\":\"82810327953012498612382200175108254608097289209592945267796930988226249448409\", \"price\":\"0.156\", \"size\":\"626.42\", \"side\":\"SELL\", \"hash\":\"d9f87655513396f174c0e7f50a5653ffa95f4475\", \"best_bid\":\"0.122\", \"best_ask\":\"0.15\"}], \"timestamp\":\"1790267439282\", \"event_type\":\"price_change\"}"}
{"paper_only":true,"authenticated_execution":false,"real_order_submission":false,"real_capital_at_risk":false,"automatic_promotion":false,"execution_authority":false,"schema":"polymarket_v7_native_exact_arb_ws_frame_v1","model_sha":"f50147e18e02ebed76cabe900b708e4d9479e603","observer_session_id":"1790267378940-30808","session_manifest_sha256":"029412640e461b7cef08522eb6b6bce381d52d8001b3032f3af1960a7bd52ea0","feed_frame_sequence":110,"connection_epoch":1,"source_frame_valid":true,"decoded_events":2,"receive_wall_ms":1790267439826,"receive_monotonic_ns":1533904297408208,"decode_complete_monotonic_ns":1533904297485375,"graph_decision_start_ns":1533904297498125,"payload_sha256":"53eccdbde106d09bba80d8f927b86cc5c69749a1778d4252b3963f6ba54112ec","payload":"{\"market\":\"0x12ed4858fd4aa92e1a644c74273ca76f49735c114d6833f8a3edef4f19e5ebff\", \"price_changes\":[{\"asset_id\":\"18054759644013870900749170809345467324611742242067616964612696305379357034954\", \"price\":\"0.61\", \"size\":\"0\", \"side\":\"BUY\", \"hash\":\"0289e46736fb86bd006d640ead714051eeaa0fa4\", \"best_bid\":\"0.6\", \"best_ask\":\"0.66\"}, {\"asset_id\":\"35599907049186982879557420969598528789434547136942253652554709047485665633870\", \"price\":\"0.39\", \"size\":\"0\", \"side\":\"SELL\", \"hash\":\"aef827224bcbec9fdb54f95a7bf2b304601c937b\", \"best_bid\":\"0.34\", \"best_ask\":\"0.4\"}], \"timestamp\":\"1790267439831\", \"event_type\":\"price_change\"}"}
